{
 "cells": [
  {
   "cell_type": "markdown",
   "metadata": {},
   "source": [
    "使用RandomOverSampler进行过采样，过拟合现象比较严重"
   ]
  },
  {
   "cell_type": "code",
   "execution_count": 33,
   "metadata": {},
   "outputs": [],
   "source": [
    "import numpy as np \n",
    "import matplotlib.pyplot as plt \n",
    "import pandas as pd \n",
    "import seaborn as sns\n",
    "import imblearn\n",
    "from plotnine import *"
   ]
  },
  {
   "cell_type": "code",
   "execution_count": 34,
   "metadata": {},
   "outputs": [],
   "source": [
    "raw_structure_data = pd.read_csv('csv_building_structure.csv')"
   ]
  },
  {
   "cell_type": "code",
   "execution_count": 35,
   "metadata": {},
   "outputs": [
    {
     "name": "stdout",
     "output_type": "stream",
     "text": [
      "<class 'pandas.core.frame.DataFrame'>\n",
      "Int64Index: 762094 entries, 0 to 762105\n",
      "Data columns (total 31 columns):\n",
      " #   Column                                  Non-Null Count   Dtype \n",
      "---  ------                                  --------------   ----- \n",
      " 0   building_id                             762094 non-null  int64 \n",
      " 1   district_id                             762094 non-null  int64 \n",
      " 2   vdcmun_id                               762094 non-null  int64 \n",
      " 3   ward_id                                 762094 non-null  int64 \n",
      " 4   count_floors_pre_eq                     762094 non-null  int64 \n",
      " 5   count_floors_post_eq                    762094 non-null  int64 \n",
      " 6   age_building                            762094 non-null  int64 \n",
      " 7   plinth_area_sq_ft                       762094 non-null  int64 \n",
      " 8   height_ft_pre_eq                        762094 non-null  int64 \n",
      " 9   height_ft_post_eq                       762094 non-null  int64 \n",
      " 10  land_surface_condition                  762094 non-null  object\n",
      " 11  foundation_type                         762094 non-null  object\n",
      " 12  roof_type                               762094 non-null  object\n",
      " 13  ground_floor_type                       762094 non-null  object\n",
      " 14  other_floor_type                        762094 non-null  object\n",
      " 15  position                                762094 non-null  object\n",
      " 16  plan_configuration                      762094 non-null  object\n",
      " 17  has_superstructure_adobe_mud            762094 non-null  int64 \n",
      " 18  has_superstructure_mud_mortar_stone     762094 non-null  int64 \n",
      " 19  has_superstructure_stone_flag           762094 non-null  int64 \n",
      " 20  has_superstructure_cement_mortar_stone  762094 non-null  int64 \n",
      " 21  has_superstructure_mud_mortar_brick     762094 non-null  int64 \n",
      " 22  has_superstructure_cement_mortar_brick  762094 non-null  int64 \n",
      " 23  has_superstructure_timber               762094 non-null  int64 \n",
      " 24  has_superstructure_bamboo               762094 non-null  int64 \n",
      " 25  has_superstructure_rc_non_engineered    762094 non-null  int64 \n",
      " 26  has_superstructure_rc_engineered        762094 non-null  int64 \n",
      " 27  has_superstructure_other                762094 non-null  int64 \n",
      " 28  condition_post_eq                       762094 non-null  object\n",
      " 29  damage_grade                            762094 non-null  object\n",
      " 30  technical_solution_proposed             762094 non-null  object\n",
      "dtypes: int64(21), object(10)\n",
      "memory usage: 186.1+ MB\n"
     ]
    }
   ],
   "source": [
    "raw_structure_data.dropna(inplace=True)\n",
    "raw_structure_data.info()"
   ]
  },
  {
   "cell_type": "code",
   "execution_count": 17,
   "metadata": {},
   "outputs": [],
   "source": [
    "distrct_map = pd.read_csv(\"ward_vdcmun_district_name_mapping.csv\")\n",
    "structure_data = pd.merge(raw_structure_data, distrct_map, on=['ward_id', 'vdcmun_id', 'district_id'], how='left')"
   ]
  },
  {
   "cell_type": "code",
   "execution_count": 18,
   "metadata": {},
   "outputs": [],
   "source": [
    "structure_data = structure_data.drop(['building_id', 'district_id', 'vdcmun_id', 'ward_id', 'count_floors_post_eq', \\\n",
    "    'height_ft_post_eq', 'condition_post_eq', 'technical_solution_proposed', 'vdcmun_name'], axis=1)"
   ]
  },
  {
   "cell_type": "code",
   "execution_count": 19,
   "metadata": {},
   "outputs": [
    {
     "data": {
      "text/plain": [
       "Grade 5    275766\n",
       "Grade 4    183844\n",
       "Grade 3    136412\n",
       "Grade 2     87257\n",
       "Grade 1     78815\n",
       "Name: damage_grade, dtype: int64"
      ]
     },
     "execution_count": 19,
     "metadata": {},
     "output_type": "execute_result"
    }
   ],
   "source": [
    "structure_data['damage_grade'].value_counts()"
   ]
  },
  {
   "cell_type": "code",
   "execution_count": 20,
   "metadata": {},
   "outputs": [
    {
     "name": "stdout",
     "output_type": "stream",
     "text": [
      "Mud mortar-Stone/Brick    628705\n",
      "Bamboo/Timber              57472\n",
      "Cement-Stone/Brick         39245\n",
      "RC                         32120\n",
      "Other                       4552\n",
      "Name: foundation_type, dtype: int64\n"
     ]
    }
   ],
   "source": [
    "print(structure_data.foundation_type.value_counts())"
   ]
  },
  {
   "cell_type": "code",
   "execution_count": 21,
   "metadata": {},
   "outputs": [],
   "source": [
    "structure_data['foundation_type'] = structure_data['foundation_type'].replace(['Bamboo/Timber', 'Cement-Stone/Brick', 'RC'], 'Other')\n"
   ]
  },
  {
   "cell_type": "code",
   "execution_count": 22,
   "metadata": {},
   "outputs": [],
   "source": [
    "numeric_variables = structure_data.select_dtypes(include=['float64', 'int64'])\n",
    "\n",
    "log_transformed_data = np.log1p(numeric_variables)\n",
    "\n",
    "structure_data[numeric_variables.columns] = log_transformed_data"
   ]
  },
  {
   "cell_type": "code",
   "execution_count": 23,
   "metadata": {},
   "outputs": [],
   "source": [
    "severity_mapping = {'Grade 1': 1, 'Grade 2': 2, 'Grade 3': 3, 'Grade 4': 4, 'Grade 5': 5}\n",
    "structure_data['damage_grade'] = structure_data['damage_grade'].map(severity_mapping)"
   ]
  },
  {
   "cell_type": "code",
   "execution_count": 24,
   "metadata": {},
   "outputs": [],
   "source": [
    "columns_to_encode = ['land_surface_condition', 'foundation_type', 'roof_type', 'ground_floor_type',\n",
    "                      'other_floor_type', 'position', 'plan_configuration']\n",
    "\n",
    "structure_data = pd.get_dummies(structure_data, columns=columns_to_encode)"
   ]
  },
  {
   "cell_type": "code",
   "execution_count": 25,
   "metadata": {},
   "outputs": [
    {
     "data": {
      "text/plain": [
       "Kavrepalanchok    98019\n",
       "Makwanpur         90994\n",
       "Dhading           89122\n",
       "Sindhupalchok     88741\n",
       "Gorkha            78074\n",
       "Nuwakot           77148\n",
       "Sindhuli          68749\n",
       "Dolakha           60639\n",
       "Ramechhap         58612\n",
       "Okhaldhunga       39352\n",
       "Rasuwa            12644\n",
       "Name: district_name, dtype: int64"
      ]
     },
     "execution_count": 25,
     "metadata": {},
     "output_type": "execute_result"
    }
   ],
   "source": [
    "structure_data['district_name'].value_counts()"
   ]
  },
  {
   "cell_type": "code",
   "execution_count": 26,
   "metadata": {},
   "outputs": [],
   "source": [
    "grouped_dataframes = structure_data.groupby('district_name')\n",
    "district_dataframes = {name: group for name, group in grouped_dataframes}"
   ]
  },
  {
   "cell_type": "code",
   "execution_count": null,
   "metadata": {},
   "outputs": [
    {
     "name": "stderr",
     "output_type": "stream",
     "text": [
      "exception calling callback for <Future at 0x25710043e50 state=finished raised TerminatedWorkerError>\n",
      "Traceback (most recent call last):\n",
      "  File \"D:\\anaconda1\\lib\\site-packages\\joblib\\externals\\loky\\_base.py\", line 625, in _invoke_callbacks\n",
      "  File \"D:\\anaconda1\\lib\\site-packages\\joblib\\parallel.py\", line 359, in __call__\n",
      "    **backend_params\n",
      "  File \"D:\\anaconda1\\lib\\site-packages\\joblib\\parallel.py\", line 794, in dispatch_next\n",
      "    # registers the task outcome (TASK_ERROR or TASK_DONE), and schedules\n",
      "  File \"D:\\anaconda1\\lib\\site-packages\\joblib\\parallel.py\", line 861, in dispatch_one_batch\n",
      "    with self.parallel._lock:\n",
      "  File \"D:\\anaconda1\\lib\\site-packages\\joblib\\parallel.py\", line 779, in _dispatch\n",
      "  File \"D:\\anaconda1\\lib\\site-packages\\joblib\\_parallel_backends.py\", line 531, in apply_async\n",
      "    \"\"\"Shutdown the process or thread pool\"\"\"\n",
      "  File \"D:\\anaconda1\\lib\\site-packages\\joblib\\externals\\loky\\reusable_executor.py\", line 177, in submit\n",
      "    mp.util.debug(\n",
      "  File \"D:\\anaconda1\\lib\\site-packages\\joblib\\externals\\loky\\process_executor.py\", line 1115, in submit\n",
      "    # of the main loop of executor_manager_thread from another thread (e.g.\n",
      "joblib.externals.loky.process_executor.TerminatedWorkerError: A worker process managed by the executor was unexpectedly terminated. This could be caused by a segmentation fault while calling the function or by an excessive memory usage causing the Operating System to kill the worker.\n",
      "\n",
      "exception calling callback for <Future at 0x2571009e3d0 state=finished raised TerminatedWorkerError>\n",
      "Traceback (most recent call last):\n",
      "  File \"D:\\anaconda1\\lib\\site-packages\\joblib\\externals\\loky\\_base.py\", line 625, in _invoke_callbacks\n",
      "  File \"D:\\anaconda1\\lib\\site-packages\\joblib\\parallel.py\", line 359, in __call__\n",
      "    **backend_params\n",
      "  File \"D:\\anaconda1\\lib\\site-packages\\joblib\\parallel.py\", line 794, in dispatch_next\n",
      "    # registers the task outcome (TASK_ERROR or TASK_DONE), and schedules\n",
      "  File \"D:\\anaconda1\\lib\\site-packages\\joblib\\parallel.py\", line 861, in dispatch_one_batch\n",
      "    with self.parallel._lock:\n",
      "  File \"D:\\anaconda1\\lib\\site-packages\\joblib\\parallel.py\", line 779, in _dispatch\n",
      "  File \"D:\\anaconda1\\lib\\site-packages\\joblib\\_parallel_backends.py\", line 531, in apply_async\n",
      "    \"\"\"Shutdown the process or thread pool\"\"\"\n",
      "  File \"D:\\anaconda1\\lib\\site-packages\\joblib\\externals\\loky\\reusable_executor.py\", line 177, in submit\n",
      "    mp.util.debug(\n",
      "  File \"D:\\anaconda1\\lib\\site-packages\\joblib\\externals\\loky\\process_executor.py\", line 1115, in submit\n",
      "    # of the main loop of executor_manager_thread from another thread (e.g.\n",
      "joblib.externals.loky.process_executor.TerminatedWorkerError: A worker process managed by the executor was unexpectedly terminated. This could be caused by a segmentation fault while calling the function or by an excessive memory usage causing the Operating System to kill the worker.\n",
      "\n",
      "exception calling callback for <Future at 0x25703d68130 state=finished raised TerminatedWorkerError>\n",
      "Traceback (most recent call last):\n",
      "  File \"D:\\anaconda1\\lib\\site-packages\\joblib\\externals\\loky\\_base.py\", line 625, in _invoke_callbacks\n",
      "  File \"D:\\anaconda1\\lib\\site-packages\\joblib\\parallel.py\", line 359, in __call__\n",
      "    **backend_params\n",
      "  File \"D:\\anaconda1\\lib\\site-packages\\joblib\\parallel.py\", line 794, in dispatch_next\n",
      "    # registers the task outcome (TASK_ERROR or TASK_DONE), and schedules\n",
      "  File \"D:\\anaconda1\\lib\\site-packages\\joblib\\parallel.py\", line 861, in dispatch_one_batch\n",
      "    with self.parallel._lock:\n",
      "  File \"D:\\anaconda1\\lib\\site-packages\\joblib\\parallel.py\", line 779, in _dispatch\n",
      "  File \"D:\\anaconda1\\lib\\site-packages\\joblib\\_parallel_backends.py\", line 531, in apply_async\n",
      "    \"\"\"Shutdown the process or thread pool\"\"\"\n",
      "  File \"D:\\anaconda1\\lib\\site-packages\\joblib\\externals\\loky\\reusable_executor.py\", line 177, in submit\n",
      "    mp.util.debug(\n",
      "  File \"D:\\anaconda1\\lib\\site-packages\\joblib\\externals\\loky\\process_executor.py\", line 1115, in submit\n",
      "    # of the main loop of executor_manager_thread from another thread (e.g.\n",
      "joblib.externals.loky.process_executor.TerminatedWorkerError: A worker process managed by the executor was unexpectedly terminated. This could be caused by a segmentation fault while calling the function or by an excessive memory usage causing the Operating System to kill the worker.\n",
      "\n",
      "exception calling callback for <Future at 0x25703d7de20 state=finished raised TerminatedWorkerError>\n",
      "Traceback (most recent call last):\n",
      "  File \"D:\\anaconda1\\lib\\site-packages\\joblib\\externals\\loky\\_base.py\", line 625, in _invoke_callbacks\n",
      "  File \"D:\\anaconda1\\lib\\site-packages\\joblib\\parallel.py\", line 359, in __call__\n",
      "    **backend_params\n",
      "  File \"D:\\anaconda1\\lib\\site-packages\\joblib\\parallel.py\", line 794, in dispatch_next\n",
      "    # registers the task outcome (TASK_ERROR or TASK_DONE), and schedules\n",
      "  File \"D:\\anaconda1\\lib\\site-packages\\joblib\\parallel.py\", line 861, in dispatch_one_batch\n",
      "    with self.parallel._lock:\n",
      "  File \"D:\\anaconda1\\lib\\site-packages\\joblib\\parallel.py\", line 779, in _dispatch\n",
      "  File \"D:\\anaconda1\\lib\\site-packages\\joblib\\_parallel_backends.py\", line 531, in apply_async\n",
      "    \"\"\"Shutdown the process or thread pool\"\"\"\n",
      "  File \"D:\\anaconda1\\lib\\site-packages\\joblib\\externals\\loky\\reusable_executor.py\", line 177, in submit\n",
      "    mp.util.debug(\n",
      "  File \"D:\\anaconda1\\lib\\site-packages\\joblib\\externals\\loky\\process_executor.py\", line 1115, in submit\n",
      "    # of the main loop of executor_manager_thread from another thread (e.g.\n",
      "joblib.externals.loky.process_executor.TerminatedWorkerError: A worker process managed by the executor was unexpectedly terminated. This could be caused by a segmentation fault while calling the function or by an excessive memory usage causing the Operating System to kill the worker.\n",
      "\n",
      "D:\\anaconda1\\lib\\site-packages\\sklearn\\model_selection\\_validation.py:372: FitFailedWarning: \n",
      "5 fits failed out of a total of 5.\n",
      "The score on these train-test partitions for these parameters will be set to nan.\n",
      "If these failures are not expected, you can try to debug them by setting error_score='raise'.\n",
      "\n",
      "Below are more details about the failures:\n",
      "--------------------------------------------------------------------------------\n",
      "4 fits failed with the following error:\n",
      "Traceback (most recent call last):\n",
      "  File \"D:\\anaconda1\\lib\\site-packages\\sklearn\\model_selection\\_validation.py\", line 680, in _fit_and_score\n",
      "    estimator.fit(X_train, y_train, **fit_params)\n",
      "  File \"D:\\anaconda1\\lib\\site-packages\\sklearn\\ensemble\\_forest.py\", line 450, in fit\n",
      "    trees = Parallel(\n",
      "  File \"D:\\anaconda1\\lib\\site-packages\\joblib\\parallel.py\", line 1056, in __call__\n",
      "  File \"D:\\anaconda1\\lib\\site-packages\\joblib\\parallel.py\", line 935, in retrieve\n",
      "    Read more in the :ref:`User Guide <parallel>`.\n",
      "  File \"D:\\anaconda1\\lib\\site-packages\\joblib\\_parallel_backends.py\", line 542, in wrap_future_result\n",
      "    def configure(self, n_jobs=1, parallel=None, prefer=None, require=None,\n",
      "  File \"D:\\anaconda1\\lib\\concurrent\\futures\\_base.py\", line 446, in result\n",
      "    return self.__get_result()\n",
      "  File \"D:\\anaconda1\\lib\\concurrent\\futures\\_base.py\", line 391, in __get_result\n",
      "    raise self._exception\n",
      "  File \"D:\\anaconda1\\lib\\site-packages\\joblib\\externals\\loky\\_base.py\", line 625, in _invoke_callbacks\n",
      "  File \"D:\\anaconda1\\lib\\site-packages\\joblib\\parallel.py\", line 359, in __call__\n",
      "    **backend_params\n",
      "  File \"D:\\anaconda1\\lib\\site-packages\\joblib\\parallel.py\", line 794, in dispatch_next\n",
      "    # registers the task outcome (TASK_ERROR or TASK_DONE), and schedules\n",
      "  File \"D:\\anaconda1\\lib\\site-packages\\joblib\\parallel.py\", line 861, in dispatch_one_batch\n",
      "    with self.parallel._lock:\n",
      "  File \"D:\\anaconda1\\lib\\site-packages\\joblib\\parallel.py\", line 779, in _dispatch\n",
      "  File \"D:\\anaconda1\\lib\\site-packages\\joblib\\_parallel_backends.py\", line 531, in apply_async\n",
      "    \"\"\"Shutdown the process or thread pool\"\"\"\n",
      "  File \"D:\\anaconda1\\lib\\site-packages\\joblib\\externals\\loky\\reusable_executor.py\", line 177, in submit\n",
      "    mp.util.debug(\n",
      "  File \"D:\\anaconda1\\lib\\site-packages\\joblib\\externals\\loky\\process_executor.py\", line 1115, in submit\n",
      "    # of the main loop of executor_manager_thread from another thread (e.g.\n",
      "joblib.externals.loky.process_executor.TerminatedWorkerError: A worker process managed by the executor was unexpectedly terminated. This could be caused by a segmentation fault while calling the function or by an excessive memory usage causing the Operating System to kill the worker.\n",
      "\n",
      "\n",
      "--------------------------------------------------------------------------------\n",
      "1 fits failed with the following error:\n",
      "Traceback (most recent call last):\n",
      "  File \"D:\\anaconda1\\lib\\site-packages\\sklearn\\model_selection\\_validation.py\", line 680, in _fit_and_score\n",
      "    estimator.fit(X_train, y_train, **fit_params)\n",
      "  File \"D:\\anaconda1\\lib\\site-packages\\sklearn\\ensemble\\_forest.py\", line 450, in fit\n",
      "    trees = Parallel(\n",
      "  File \"D:\\anaconda1\\lib\\site-packages\\joblib\\parallel.py\", line 1056, in __call__\n",
      "  File \"D:\\anaconda1\\lib\\site-packages\\joblib\\parallel.py\", line 935, in retrieve\n",
      "    Read more in the :ref:`User Guide <parallel>`.\n",
      "  File \"D:\\anaconda1\\lib\\site-packages\\joblib\\_parallel_backends.py\", line 542, in wrap_future_result\n",
      "    def configure(self, n_jobs=1, parallel=None, prefer=None, require=None,\n",
      "  File \"D:\\anaconda1\\lib\\concurrent\\futures\\_base.py\", line 446, in result\n",
      "    return self.__get_result()\n",
      "  File \"D:\\anaconda1\\lib\\concurrent\\futures\\_base.py\", line 391, in __get_result\n",
      "    raise self._exception\n",
      "joblib.externals.loky.process_executor.TerminatedWorkerError: A worker process managed by the executor was unexpectedly terminated. This could be caused by a segmentation fault while calling the function or by an excessive memory usage causing the Operating System to kill the worker.\n",
      "\n",
      "\n"
     ]
    },
    {
     "name": "stdout",
     "output_type": "stream",
     "text": [
      "Cross-validation scores for Dhading: [nan nan nan nan nan]\n",
      "Mean cross-validation accuracy for Dhading: nan\n",
      "Accuracy of Dhading: 0.40\n"
     ]
    },
    {
     "name": "stderr",
     "output_type": "stream",
     "text": [
      "exception calling callback for <Future at 0x25703d7fa00 state=finished raised TerminatedWorkerError>\n",
      "Traceback (most recent call last):\n",
      "  File \"D:\\anaconda1\\lib\\site-packages\\joblib\\externals\\loky\\_base.py\", line 625, in _invoke_callbacks\n",
      "  File \"D:\\anaconda1\\lib\\site-packages\\joblib\\parallel.py\", line 359, in __call__\n",
      "    **backend_params\n",
      "  File \"D:\\anaconda1\\lib\\site-packages\\joblib\\parallel.py\", line 794, in dispatch_next\n",
      "    # registers the task outcome (TASK_ERROR or TASK_DONE), and schedules\n",
      "  File \"D:\\anaconda1\\lib\\site-packages\\joblib\\parallel.py\", line 861, in dispatch_one_batch\n",
      "    with self.parallel._lock:\n",
      "  File \"D:\\anaconda1\\lib\\site-packages\\joblib\\parallel.py\", line 779, in _dispatch\n",
      "  File \"D:\\anaconda1\\lib\\site-packages\\joblib\\_parallel_backends.py\", line 531, in apply_async\n",
      "    \"\"\"Shutdown the process or thread pool\"\"\"\n",
      "  File \"D:\\anaconda1\\lib\\site-packages\\joblib\\externals\\loky\\reusable_executor.py\", line 177, in submit\n",
      "    mp.util.debug(\n",
      "  File \"D:\\anaconda1\\lib\\site-packages\\joblib\\externals\\loky\\process_executor.py\", line 1115, in submit\n",
      "    # of the main loop of executor_manager_thread from another thread (e.g.\n",
      "joblib.externals.loky.process_executor.TerminatedWorkerError: A worker process managed by the executor was unexpectedly terminated. This could be caused by a segmentation fault while calling the function or by an excessive memory usage causing the Operating System to kill the worker.\n",
      "\n",
      "exception calling callback for <Future at 0x25703da6f10 state=finished raised TerminatedWorkerError>\n",
      "Traceback (most recent call last):\n",
      "  File \"D:\\anaconda1\\lib\\site-packages\\joblib\\externals\\loky\\_base.py\", line 625, in _invoke_callbacks\n",
      "  File \"D:\\anaconda1\\lib\\site-packages\\joblib\\parallel.py\", line 359, in __call__\n",
      "    **backend_params\n",
      "  File \"D:\\anaconda1\\lib\\site-packages\\joblib\\parallel.py\", line 794, in dispatch_next\n",
      "    # registers the task outcome (TASK_ERROR or TASK_DONE), and schedules\n",
      "  File \"D:\\anaconda1\\lib\\site-packages\\joblib\\parallel.py\", line 861, in dispatch_one_batch\n",
      "    with self.parallel._lock:\n",
      "  File \"D:\\anaconda1\\lib\\site-packages\\joblib\\parallel.py\", line 779, in _dispatch\n",
      "  File \"D:\\anaconda1\\lib\\site-packages\\joblib\\_parallel_backends.py\", line 531, in apply_async\n",
      "    \"\"\"Shutdown the process or thread pool\"\"\"\n",
      "  File \"D:\\anaconda1\\lib\\site-packages\\joblib\\externals\\loky\\reusable_executor.py\", line 177, in submit\n",
      "    mp.util.debug(\n",
      "  File \"D:\\anaconda1\\lib\\site-packages\\joblib\\externals\\loky\\process_executor.py\", line 1115, in submit\n",
      "    # of the main loop of executor_manager_thread from another thread (e.g.\n",
      "joblib.externals.loky.process_executor.TerminatedWorkerError: A worker process managed by the executor was unexpectedly terminated. This could be caused by a segmentation fault while calling the function or by an excessive memory usage causing the Operating System to kill the worker.\n",
      "\n",
      "exception calling callback for <Future at 0x2570c51e250 state=finished raised TerminatedWorkerError>\n",
      "Traceback (most recent call last):\n",
      "  File \"D:\\anaconda1\\lib\\site-packages\\joblib\\externals\\loky\\_base.py\", line 625, in _invoke_callbacks\n",
      "  File \"D:\\anaconda1\\lib\\site-packages\\joblib\\parallel.py\", line 359, in __call__\n",
      "    **backend_params\n",
      "  File \"D:\\anaconda1\\lib\\site-packages\\joblib\\parallel.py\", line 794, in dispatch_next\n",
      "    # registers the task outcome (TASK_ERROR or TASK_DONE), and schedules\n",
      "  File \"D:\\anaconda1\\lib\\site-packages\\joblib\\parallel.py\", line 861, in dispatch_one_batch\n",
      "    with self.parallel._lock:\n",
      "  File \"D:\\anaconda1\\lib\\site-packages\\joblib\\parallel.py\", line 779, in _dispatch\n",
      "  File \"D:\\anaconda1\\lib\\site-packages\\joblib\\_parallel_backends.py\", line 531, in apply_async\n",
      "    \"\"\"Shutdown the process or thread pool\"\"\"\n",
      "  File \"D:\\anaconda1\\lib\\site-packages\\joblib\\externals\\loky\\reusable_executor.py\", line 177, in submit\n",
      "    mp.util.debug(\n",
      "  File \"D:\\anaconda1\\lib\\site-packages\\joblib\\externals\\loky\\process_executor.py\", line 1115, in submit\n",
      "    # of the main loop of executor_manager_thread from another thread (e.g.\n",
      "joblib.externals.loky.process_executor.TerminatedWorkerError: A worker process managed by the executor was unexpectedly terminated. This could be caused by a segmentation fault while calling the function or by an excessive memory usage causing the Operating System to kill the worker.\n",
      "\n",
      "exception calling callback for <Future at 0x2570c535d90 state=finished raised TerminatedWorkerError>\n",
      "Traceback (most recent call last):\n",
      "  File \"D:\\anaconda1\\lib\\site-packages\\joblib\\externals\\loky\\_base.py\", line 625, in _invoke_callbacks\n",
      "  File \"D:\\anaconda1\\lib\\site-packages\\joblib\\parallel.py\", line 359, in __call__\n",
      "    **backend_params\n",
      "  File \"D:\\anaconda1\\lib\\site-packages\\joblib\\parallel.py\", line 794, in dispatch_next\n",
      "    # registers the task outcome (TASK_ERROR or TASK_DONE), and schedules\n",
      "  File \"D:\\anaconda1\\lib\\site-packages\\joblib\\parallel.py\", line 861, in dispatch_one_batch\n",
      "    with self.parallel._lock:\n",
      "  File \"D:\\anaconda1\\lib\\site-packages\\joblib\\parallel.py\", line 779, in _dispatch\n",
      "  File \"D:\\anaconda1\\lib\\site-packages\\joblib\\_parallel_backends.py\", line 531, in apply_async\n",
      "    \"\"\"Shutdown the process or thread pool\"\"\"\n",
      "  File \"D:\\anaconda1\\lib\\site-packages\\joblib\\externals\\loky\\reusable_executor.py\", line 177, in submit\n",
      "    mp.util.debug(\n",
      "  File \"D:\\anaconda1\\lib\\site-packages\\joblib\\externals\\loky\\process_executor.py\", line 1115, in submit\n",
      "    # of the main loop of executor_manager_thread from another thread (e.g.\n",
      "joblib.externals.loky.process_executor.TerminatedWorkerError: A worker process managed by the executor was unexpectedly terminated. This could be caused by a segmentation fault while calling the function or by an excessive memory usage causing the Operating System to kill the worker.\n",
      "\n",
      "exception calling callback for <Future at 0x257036770d0 state=finished raised TerminatedWorkerError>\n",
      "Traceback (most recent call last):\n",
      "  File \"D:\\anaconda1\\lib\\site-packages\\joblib\\externals\\loky\\_base.py\", line 625, in _invoke_callbacks\n",
      "  File \"D:\\anaconda1\\lib\\site-packages\\joblib\\parallel.py\", line 359, in __call__\n",
      "    **backend_params\n",
      "  File \"D:\\anaconda1\\lib\\site-packages\\joblib\\parallel.py\", line 794, in dispatch_next\n",
      "    # registers the task outcome (TASK_ERROR or TASK_DONE), and schedules\n",
      "  File \"D:\\anaconda1\\lib\\site-packages\\joblib\\parallel.py\", line 861, in dispatch_one_batch\n",
      "    with self.parallel._lock:\n",
      "  File \"D:\\anaconda1\\lib\\site-packages\\joblib\\parallel.py\", line 779, in _dispatch\n",
      "  File \"D:\\anaconda1\\lib\\site-packages\\joblib\\_parallel_backends.py\", line 531, in apply_async\n",
      "    \"\"\"Shutdown the process or thread pool\"\"\"\n",
      "  File \"D:\\anaconda1\\lib\\site-packages\\joblib\\externals\\loky\\reusable_executor.py\", line 177, in submit\n",
      "    mp.util.debug(\n",
      "  File \"D:\\anaconda1\\lib\\site-packages\\joblib\\externals\\loky\\process_executor.py\", line 1115, in submit\n",
      "    # of the main loop of executor_manager_thread from another thread (e.g.\n",
      "joblib.externals.loky.process_executor.TerminatedWorkerError: A worker process managed by the executor was unexpectedly terminated. This could be caused by a segmentation fault while calling the function or by an excessive memory usage causing the Operating System to kill the worker.\n",
      "\n",
      "D:\\anaconda1\\lib\\site-packages\\sklearn\\model_selection\\_validation.py:372: FitFailedWarning: \n",
      "5 fits failed out of a total of 5.\n",
      "The score on these train-test partitions for these parameters will be set to nan.\n",
      "If these failures are not expected, you can try to debug them by setting error_score='raise'.\n",
      "\n",
      "Below are more details about the failures:\n",
      "--------------------------------------------------------------------------------\n",
      "5 fits failed with the following error:\n",
      "Traceback (most recent call last):\n",
      "  File \"D:\\anaconda1\\lib\\site-packages\\sklearn\\model_selection\\_validation.py\", line 680, in _fit_and_score\n",
      "    estimator.fit(X_train, y_train, **fit_params)\n",
      "  File \"D:\\anaconda1\\lib\\site-packages\\sklearn\\ensemble\\_forest.py\", line 450, in fit\n",
      "    trees = Parallel(\n",
      "  File \"D:\\anaconda1\\lib\\site-packages\\joblib\\parallel.py\", line 1056, in __call__\n",
      "  File \"D:\\anaconda1\\lib\\site-packages\\joblib\\parallel.py\", line 935, in retrieve\n",
      "    Read more in the :ref:`User Guide <parallel>`.\n",
      "  File \"D:\\anaconda1\\lib\\site-packages\\joblib\\_parallel_backends.py\", line 542, in wrap_future_result\n",
      "    def configure(self, n_jobs=1, parallel=None, prefer=None, require=None,\n",
      "  File \"D:\\anaconda1\\lib\\concurrent\\futures\\_base.py\", line 446, in result\n",
      "    return self.__get_result()\n",
      "  File \"D:\\anaconda1\\lib\\concurrent\\futures\\_base.py\", line 391, in __get_result\n",
      "    raise self._exception\n",
      "  File \"D:\\anaconda1\\lib\\site-packages\\joblib\\externals\\loky\\_base.py\", line 625, in _invoke_callbacks\n",
      "  File \"D:\\anaconda1\\lib\\site-packages\\joblib\\parallel.py\", line 359, in __call__\n",
      "    **backend_params\n",
      "  File \"D:\\anaconda1\\lib\\site-packages\\joblib\\parallel.py\", line 794, in dispatch_next\n",
      "    # registers the task outcome (TASK_ERROR or TASK_DONE), and schedules\n",
      "  File \"D:\\anaconda1\\lib\\site-packages\\joblib\\parallel.py\", line 861, in dispatch_one_batch\n",
      "    with self.parallel._lock:\n",
      "  File \"D:\\anaconda1\\lib\\site-packages\\joblib\\parallel.py\", line 779, in _dispatch\n",
      "  File \"D:\\anaconda1\\lib\\site-packages\\joblib\\_parallel_backends.py\", line 531, in apply_async\n",
      "    \"\"\"Shutdown the process or thread pool\"\"\"\n",
      "  File \"D:\\anaconda1\\lib\\site-packages\\joblib\\externals\\loky\\reusable_executor.py\", line 177, in submit\n",
      "    mp.util.debug(\n",
      "  File \"D:\\anaconda1\\lib\\site-packages\\joblib\\externals\\loky\\process_executor.py\", line 1115, in submit\n",
      "    # of the main loop of executor_manager_thread from another thread (e.g.\n",
      "joblib.externals.loky.process_executor.TerminatedWorkerError: A worker process managed by the executor was unexpectedly terminated. This could be caused by a segmentation fault while calling the function or by an excessive memory usage causing the Operating System to kill the worker.\n",
      "\n",
      "\n"
     ]
    },
    {
     "name": "stdout",
     "output_type": "stream",
     "text": [
      "Cross-validation scores for Dolakha: [nan nan nan nan nan]\n",
      "Mean cross-validation accuracy for Dolakha: nan\n",
      "Accuracy of Dolakha: 0.39\n"
     ]
    },
    {
     "name": "stderr",
     "output_type": "stream",
     "text": [
      "exception calling callback for <Future at 0x2570c53ceb0 state=finished raised TerminatedWorkerError>\n",
      "Traceback (most recent call last):\n",
      "  File \"D:\\anaconda1\\lib\\site-packages\\joblib\\externals\\loky\\_base.py\", line 625, in _invoke_callbacks\n",
      "  File \"D:\\anaconda1\\lib\\site-packages\\joblib\\parallel.py\", line 359, in __call__\n",
      "    **backend_params\n",
      "  File \"D:\\anaconda1\\lib\\site-packages\\joblib\\parallel.py\", line 794, in dispatch_next\n",
      "    # registers the task outcome (TASK_ERROR or TASK_DONE), and schedules\n",
      "  File \"D:\\anaconda1\\lib\\site-packages\\joblib\\parallel.py\", line 861, in dispatch_one_batch\n",
      "    with self.parallel._lock:\n",
      "  File \"D:\\anaconda1\\lib\\site-packages\\joblib\\parallel.py\", line 779, in _dispatch\n",
      "  File \"D:\\anaconda1\\lib\\site-packages\\joblib\\_parallel_backends.py\", line 531, in apply_async\n",
      "    \"\"\"Shutdown the process or thread pool\"\"\"\n",
      "  File \"D:\\anaconda1\\lib\\site-packages\\joblib\\externals\\loky\\reusable_executor.py\", line 177, in submit\n",
      "    mp.util.debug(\n",
      "  File \"D:\\anaconda1\\lib\\site-packages\\joblib\\externals\\loky\\process_executor.py\", line 1115, in submit\n",
      "    # of the main loop of executor_manager_thread from another thread (e.g.\n",
      "joblib.externals.loky.process_executor.TerminatedWorkerError: A worker process managed by the executor was unexpectedly terminated. This could be caused by a segmentation fault while calling the function or by an excessive memory usage causing the Operating System to kill the worker.\n",
      "\n",
      "exception calling callback for <Future at 0x25703ca1460 state=finished raised TerminatedWorkerError>\n",
      "Traceback (most recent call last):\n",
      "  File \"D:\\anaconda1\\lib\\site-packages\\joblib\\externals\\loky\\_base.py\", line 625, in _invoke_callbacks\n",
      "  File \"D:\\anaconda1\\lib\\site-packages\\joblib\\parallel.py\", line 359, in __call__\n",
      "    **backend_params\n",
      "  File \"D:\\anaconda1\\lib\\site-packages\\joblib\\parallel.py\", line 794, in dispatch_next\n",
      "    # registers the task outcome (TASK_ERROR or TASK_DONE), and schedules\n",
      "  File \"D:\\anaconda1\\lib\\site-packages\\joblib\\parallel.py\", line 861, in dispatch_one_batch\n",
      "    with self.parallel._lock:\n",
      "  File \"D:\\anaconda1\\lib\\site-packages\\joblib\\parallel.py\", line 779, in _dispatch\n",
      "  File \"D:\\anaconda1\\lib\\site-packages\\joblib\\_parallel_backends.py\", line 531, in apply_async\n",
      "    \"\"\"Shutdown the process or thread pool\"\"\"\n",
      "  File \"D:\\anaconda1\\lib\\site-packages\\joblib\\externals\\loky\\reusable_executor.py\", line 177, in submit\n",
      "    mp.util.debug(\n",
      "  File \"D:\\anaconda1\\lib\\site-packages\\joblib\\externals\\loky\\process_executor.py\", line 1115, in submit\n",
      "    # of the main loop of executor_manager_thread from another thread (e.g.\n",
      "joblib.externals.loky.process_executor.TerminatedWorkerError: A worker process managed by the executor was unexpectedly terminated. This could be caused by a segmentation fault while calling the function or by an excessive memory usage causing the Operating System to kill the worker.\n",
      "\n",
      "exception calling callback for <Future at 0x25703dbdc70 state=finished raised TerminatedWorkerError>\n",
      "Traceback (most recent call last):\n",
      "  File \"D:\\anaconda1\\lib\\site-packages\\joblib\\externals\\loky\\_base.py\", line 625, in _invoke_callbacks\n",
      "  File \"D:\\anaconda1\\lib\\site-packages\\joblib\\parallel.py\", line 359, in __call__\n",
      "    **backend_params\n",
      "  File \"D:\\anaconda1\\lib\\site-packages\\joblib\\parallel.py\", line 794, in dispatch_next\n",
      "    # registers the task outcome (TASK_ERROR or TASK_DONE), and schedules\n",
      "  File \"D:\\anaconda1\\lib\\site-packages\\joblib\\parallel.py\", line 861, in dispatch_one_batch\n",
      "    with self.parallel._lock:\n",
      "  File \"D:\\anaconda1\\lib\\site-packages\\joblib\\parallel.py\", line 779, in _dispatch\n",
      "  File \"D:\\anaconda1\\lib\\site-packages\\joblib\\_parallel_backends.py\", line 531, in apply_async\n",
      "    \"\"\"Shutdown the process or thread pool\"\"\"\n",
      "  File \"D:\\anaconda1\\lib\\site-packages\\joblib\\externals\\loky\\reusable_executor.py\", line 177, in submit\n",
      "    mp.util.debug(\n",
      "  File \"D:\\anaconda1\\lib\\site-packages\\joblib\\externals\\loky\\process_executor.py\", line 1115, in submit\n",
      "    # of the main loop of executor_manager_thread from another thread (e.g.\n",
      "joblib.externals.loky.process_executor.TerminatedWorkerError: A worker process managed by the executor was unexpectedly terminated. This could be caused by a segmentation fault while calling the function or by an excessive memory usage causing the Operating System to kill the worker.\n",
      "\n",
      "exception calling callback for <Future at 0x25703dc1a30 state=finished raised TerminatedWorkerError>\n",
      "Traceback (most recent call last):\n",
      "  File \"D:\\anaconda1\\lib\\site-packages\\joblib\\externals\\loky\\_base.py\", line 625, in _invoke_callbacks\n",
      "  File \"D:\\anaconda1\\lib\\site-packages\\joblib\\parallel.py\", line 359, in __call__\n",
      "    **backend_params\n",
      "  File \"D:\\anaconda1\\lib\\site-packages\\joblib\\parallel.py\", line 794, in dispatch_next\n",
      "    # registers the task outcome (TASK_ERROR or TASK_DONE), and schedules\n",
      "  File \"D:\\anaconda1\\lib\\site-packages\\joblib\\parallel.py\", line 861, in dispatch_one_batch\n",
      "    with self.parallel._lock:\n",
      "  File \"D:\\anaconda1\\lib\\site-packages\\joblib\\parallel.py\", line 779, in _dispatch\n",
      "  File \"D:\\anaconda1\\lib\\site-packages\\joblib\\_parallel_backends.py\", line 531, in apply_async\n",
      "    \"\"\"Shutdown the process or thread pool\"\"\"\n",
      "  File \"D:\\anaconda1\\lib\\site-packages\\joblib\\externals\\loky\\reusable_executor.py\", line 177, in submit\n",
      "    mp.util.debug(\n",
      "  File \"D:\\anaconda1\\lib\\site-packages\\joblib\\externals\\loky\\process_executor.py\", line 1115, in submit\n",
      "    # of the main loop of executor_manager_thread from another thread (e.g.\n",
      "joblib.externals.loky.process_executor.TerminatedWorkerError: A worker process managed by the executor was unexpectedly terminated. This could be caused by a segmentation fault while calling the function or by an excessive memory usage causing the Operating System to kill the worker.\n",
      "\n",
      "exception calling callback for <Future at 0x25703dea9a0 state=finished raised TerminatedWorkerError>\n",
      "Traceback (most recent call last):\n",
      "  File \"D:\\anaconda1\\lib\\site-packages\\joblib\\externals\\loky\\_base.py\", line 625, in _invoke_callbacks\n",
      "  File \"D:\\anaconda1\\lib\\site-packages\\joblib\\parallel.py\", line 359, in __call__\n",
      "    **backend_params\n",
      "  File \"D:\\anaconda1\\lib\\site-packages\\joblib\\parallel.py\", line 794, in dispatch_next\n",
      "    # registers the task outcome (TASK_ERROR or TASK_DONE), and schedules\n",
      "  File \"D:\\anaconda1\\lib\\site-packages\\joblib\\parallel.py\", line 861, in dispatch_one_batch\n",
      "    with self.parallel._lock:\n",
      "  File \"D:\\anaconda1\\lib\\site-packages\\joblib\\parallel.py\", line 779, in _dispatch\n",
      "  File \"D:\\anaconda1\\lib\\site-packages\\joblib\\_parallel_backends.py\", line 531, in apply_async\n",
      "    \"\"\"Shutdown the process or thread pool\"\"\"\n",
      "  File \"D:\\anaconda1\\lib\\site-packages\\joblib\\externals\\loky\\reusable_executor.py\", line 177, in submit\n",
      "    mp.util.debug(\n",
      "  File \"D:\\anaconda1\\lib\\site-packages\\joblib\\externals\\loky\\process_executor.py\", line 1115, in submit\n",
      "    # of the main loop of executor_manager_thread from another thread (e.g.\n",
      "joblib.externals.loky.process_executor.TerminatedWorkerError: A worker process managed by the executor was unexpectedly terminated. This could be caused by a segmentation fault while calling the function or by an excessive memory usage causing the Operating System to kill the worker.\n",
      "\n",
      "D:\\anaconda1\\lib\\site-packages\\sklearn\\model_selection\\_validation.py:372: FitFailedWarning: \n",
      "5 fits failed out of a total of 5.\n",
      "The score on these train-test partitions for these parameters will be set to nan.\n",
      "If these failures are not expected, you can try to debug them by setting error_score='raise'.\n",
      "\n",
      "Below are more details about the failures:\n",
      "--------------------------------------------------------------------------------\n",
      "5 fits failed with the following error:\n",
      "Traceback (most recent call last):\n",
      "  File \"D:\\anaconda1\\lib\\site-packages\\sklearn\\model_selection\\_validation.py\", line 680, in _fit_and_score\n",
      "    estimator.fit(X_train, y_train, **fit_params)\n",
      "  File \"D:\\anaconda1\\lib\\site-packages\\sklearn\\ensemble\\_forest.py\", line 450, in fit\n",
      "    trees = Parallel(\n",
      "  File \"D:\\anaconda1\\lib\\site-packages\\joblib\\parallel.py\", line 1056, in __call__\n",
      "  File \"D:\\anaconda1\\lib\\site-packages\\joblib\\parallel.py\", line 935, in retrieve\n",
      "    Read more in the :ref:`User Guide <parallel>`.\n",
      "  File \"D:\\anaconda1\\lib\\site-packages\\joblib\\_parallel_backends.py\", line 542, in wrap_future_result\n",
      "    def configure(self, n_jobs=1, parallel=None, prefer=None, require=None,\n",
      "  File \"D:\\anaconda1\\lib\\concurrent\\futures\\_base.py\", line 446, in result\n",
      "    return self.__get_result()\n",
      "  File \"D:\\anaconda1\\lib\\concurrent\\futures\\_base.py\", line 391, in __get_result\n",
      "    raise self._exception\n",
      "  File \"D:\\anaconda1\\lib\\site-packages\\joblib\\externals\\loky\\_base.py\", line 625, in _invoke_callbacks\n",
      "  File \"D:\\anaconda1\\lib\\site-packages\\joblib\\parallel.py\", line 359, in __call__\n",
      "    **backend_params\n",
      "  File \"D:\\anaconda1\\lib\\site-packages\\joblib\\parallel.py\", line 794, in dispatch_next\n",
      "    # registers the task outcome (TASK_ERROR or TASK_DONE), and schedules\n",
      "  File \"D:\\anaconda1\\lib\\site-packages\\joblib\\parallel.py\", line 861, in dispatch_one_batch\n",
      "    with self.parallel._lock:\n",
      "  File \"D:\\anaconda1\\lib\\site-packages\\joblib\\parallel.py\", line 779, in _dispatch\n",
      "  File \"D:\\anaconda1\\lib\\site-packages\\joblib\\_parallel_backends.py\", line 531, in apply_async\n",
      "    \"\"\"Shutdown the process or thread pool\"\"\"\n",
      "  File \"D:\\anaconda1\\lib\\site-packages\\joblib\\externals\\loky\\reusable_executor.py\", line 177, in submit\n",
      "    mp.util.debug(\n",
      "  File \"D:\\anaconda1\\lib\\site-packages\\joblib\\externals\\loky\\process_executor.py\", line 1115, in submit\n",
      "    # of the main loop of executor_manager_thread from another thread (e.g.\n",
      "joblib.externals.loky.process_executor.TerminatedWorkerError: A worker process managed by the executor was unexpectedly terminated. This could be caused by a segmentation fault while calling the function or by an excessive memory usage causing the Operating System to kill the worker.\n",
      "\n",
      "\n"
     ]
    },
    {
     "name": "stdout",
     "output_type": "stream",
     "text": [
      "Cross-validation scores for Gorkha: [nan nan nan nan nan]\n",
      "Mean cross-validation accuracy for Gorkha: nan\n",
      "Accuracy of Gorkha: 0.40\n"
     ]
    },
    {
     "name": "stderr",
     "output_type": "stream",
     "text": [
      "exception calling callback for <Future at 0x25703dd9ca0 state=finished raised TerminatedWorkerError>\n",
      "Traceback (most recent call last):\n",
      "  File \"D:\\anaconda1\\lib\\site-packages\\joblib\\externals\\loky\\_base.py\", line 625, in _invoke_callbacks\n",
      "  File \"D:\\anaconda1\\lib\\site-packages\\joblib\\parallel.py\", line 359, in __call__\n",
      "    **backend_params\n",
      "  File \"D:\\anaconda1\\lib\\site-packages\\joblib\\parallel.py\", line 794, in dispatch_next\n",
      "    # registers the task outcome (TASK_ERROR or TASK_DONE), and schedules\n",
      "  File \"D:\\anaconda1\\lib\\site-packages\\joblib\\parallel.py\", line 861, in dispatch_one_batch\n",
      "    with self.parallel._lock:\n",
      "  File \"D:\\anaconda1\\lib\\site-packages\\joblib\\parallel.py\", line 779, in _dispatch\n",
      "  File \"D:\\anaconda1\\lib\\site-packages\\joblib\\_parallel_backends.py\", line 531, in apply_async\n",
      "    \"\"\"Shutdown the process or thread pool\"\"\"\n",
      "  File \"D:\\anaconda1\\lib\\site-packages\\joblib\\externals\\loky\\reusable_executor.py\", line 177, in submit\n",
      "    mp.util.debug(\n",
      "  File \"D:\\anaconda1\\lib\\site-packages\\joblib\\externals\\loky\\process_executor.py\", line 1115, in submit\n",
      "    # of the main loop of executor_manager_thread from another thread (e.g.\n",
      "joblib.externals.loky.process_executor.TerminatedWorkerError: A worker process managed by the executor was unexpectedly terminated. This could be caused by a segmentation fault while calling the function or by an excessive memory usage causing the Operating System to kill the worker.\n",
      "\n",
      "exception calling callback for <Future at 0x2570369e2b0 state=finished raised TerminatedWorkerError>\n",
      "Traceback (most recent call last):\n",
      "  File \"D:\\anaconda1\\lib\\site-packages\\joblib\\externals\\loky\\_base.py\", line 625, in _invoke_callbacks\n",
      "  File \"D:\\anaconda1\\lib\\site-packages\\joblib\\parallel.py\", line 359, in __call__\n",
      "    **backend_params\n",
      "  File \"D:\\anaconda1\\lib\\site-packages\\joblib\\parallel.py\", line 794, in dispatch_next\n",
      "    # registers the task outcome (TASK_ERROR or TASK_DONE), and schedules\n",
      "  File \"D:\\anaconda1\\lib\\site-packages\\joblib\\parallel.py\", line 861, in dispatch_one_batch\n",
      "    with self.parallel._lock:\n",
      "  File \"D:\\anaconda1\\lib\\site-packages\\joblib\\parallel.py\", line 779, in _dispatch\n",
      "  File \"D:\\anaconda1\\lib\\site-packages\\joblib\\_parallel_backends.py\", line 531, in apply_async\n",
      "    \"\"\"Shutdown the process or thread pool\"\"\"\n",
      "  File \"D:\\anaconda1\\lib\\site-packages\\joblib\\externals\\loky\\reusable_executor.py\", line 177, in submit\n",
      "    mp.util.debug(\n",
      "  File \"D:\\anaconda1\\lib\\site-packages\\joblib\\externals\\loky\\process_executor.py\", line 1115, in submit\n",
      "    # of the main loop of executor_manager_thread from another thread (e.g.\n",
      "joblib.externals.loky.process_executor.TerminatedWorkerError: A worker process managed by the executor was unexpectedly terminated. This could be caused by a segmentation fault while calling the function or by an excessive memory usage causing the Operating System to kill the worker.\n",
      "\n",
      "exception calling callback for <Future at 0x257045a51c0 state=finished raised TerminatedWorkerError>\n",
      "Traceback (most recent call last):\n",
      "  File \"D:\\anaconda1\\lib\\site-packages\\joblib\\externals\\loky\\_base.py\", line 625, in _invoke_callbacks\n",
      "  File \"D:\\anaconda1\\lib\\site-packages\\joblib\\parallel.py\", line 359, in __call__\n",
      "    **backend_params\n",
      "  File \"D:\\anaconda1\\lib\\site-packages\\joblib\\parallel.py\", line 794, in dispatch_next\n",
      "    # registers the task outcome (TASK_ERROR or TASK_DONE), and schedules\n",
      "  File \"D:\\anaconda1\\lib\\site-packages\\joblib\\parallel.py\", line 861, in dispatch_one_batch\n",
      "    with self.parallel._lock:\n",
      "  File \"D:\\anaconda1\\lib\\site-packages\\joblib\\parallel.py\", line 779, in _dispatch\n",
      "  File \"D:\\anaconda1\\lib\\site-packages\\joblib\\_parallel_backends.py\", line 531, in apply_async\n",
      "    \"\"\"Shutdown the process or thread pool\"\"\"\n",
      "  File \"D:\\anaconda1\\lib\\site-packages\\joblib\\externals\\loky\\reusable_executor.py\", line 177, in submit\n",
      "    mp.util.debug(\n",
      "  File \"D:\\anaconda1\\lib\\site-packages\\joblib\\externals\\loky\\process_executor.py\", line 1115, in submit\n",
      "    # of the main loop of executor_manager_thread from another thread (e.g.\n",
      "joblib.externals.loky.process_executor.TerminatedWorkerError: A worker process managed by the executor was unexpectedly terminated. This could be caused by a segmentation fault while calling the function or by an excessive memory usage causing the Operating System to kill the worker.\n",
      "\n",
      "exception calling callback for <Future at 0x257045b9d00 state=finished raised TerminatedWorkerError>\n",
      "Traceback (most recent call last):\n",
      "  File \"D:\\anaconda1\\lib\\site-packages\\joblib\\externals\\loky\\_base.py\", line 625, in _invoke_callbacks\n",
      "  File \"D:\\anaconda1\\lib\\site-packages\\joblib\\parallel.py\", line 359, in __call__\n",
      "    **backend_params\n",
      "  File \"D:\\anaconda1\\lib\\site-packages\\joblib\\parallel.py\", line 794, in dispatch_next\n",
      "    # registers the task outcome (TASK_ERROR or TASK_DONE), and schedules\n",
      "  File \"D:\\anaconda1\\lib\\site-packages\\joblib\\parallel.py\", line 861, in dispatch_one_batch\n",
      "    with self.parallel._lock:\n",
      "  File \"D:\\anaconda1\\lib\\site-packages\\joblib\\parallel.py\", line 779, in _dispatch\n",
      "  File \"D:\\anaconda1\\lib\\site-packages\\joblib\\_parallel_backends.py\", line 531, in apply_async\n",
      "    \"\"\"Shutdown the process or thread pool\"\"\"\n",
      "  File \"D:\\anaconda1\\lib\\site-packages\\joblib\\externals\\loky\\reusable_executor.py\", line 177, in submit\n",
      "    mp.util.debug(\n",
      "  File \"D:\\anaconda1\\lib\\site-packages\\joblib\\externals\\loky\\process_executor.py\", line 1115, in submit\n",
      "    # of the main loop of executor_manager_thread from another thread (e.g.\n",
      "joblib.externals.loky.process_executor.TerminatedWorkerError: A worker process managed by the executor was unexpectedly terminated. This could be caused by a segmentation fault while calling the function or by an excessive memory usage causing the Operating System to kill the worker.\n",
      "\n",
      "exception calling callback for <Future at 0x257045d4040 state=finished raised TerminatedWorkerError>\n",
      "Traceback (most recent call last):\n",
      "  File \"D:\\anaconda1\\lib\\site-packages\\joblib\\externals\\loky\\_base.py\", line 625, in _invoke_callbacks\n",
      "  File \"D:\\anaconda1\\lib\\site-packages\\joblib\\parallel.py\", line 359, in __call__\n",
      "    **backend_params\n",
      "  File \"D:\\anaconda1\\lib\\site-packages\\joblib\\parallel.py\", line 794, in dispatch_next\n",
      "    # registers the task outcome (TASK_ERROR or TASK_DONE), and schedules\n",
      "  File \"D:\\anaconda1\\lib\\site-packages\\joblib\\parallel.py\", line 861, in dispatch_one_batch\n",
      "    with self.parallel._lock:\n",
      "  File \"D:\\anaconda1\\lib\\site-packages\\joblib\\parallel.py\", line 779, in _dispatch\n",
      "  File \"D:\\anaconda1\\lib\\site-packages\\joblib\\_parallel_backends.py\", line 531, in apply_async\n",
      "    \"\"\"Shutdown the process or thread pool\"\"\"\n",
      "  File \"D:\\anaconda1\\lib\\site-packages\\joblib\\externals\\loky\\reusable_executor.py\", line 177, in submit\n",
      "    mp.util.debug(\n",
      "  File \"D:\\anaconda1\\lib\\site-packages\\joblib\\externals\\loky\\process_executor.py\", line 1115, in submit\n",
      "    # of the main loop of executor_manager_thread from another thread (e.g.\n",
      "joblib.externals.loky.process_executor.TerminatedWorkerError: A worker process managed by the executor was unexpectedly terminated. This could be caused by a segmentation fault while calling the function or by an excessive memory usage causing the Operating System to kill the worker.\n",
      "\n",
      "D:\\anaconda1\\lib\\site-packages\\sklearn\\model_selection\\_validation.py:372: FitFailedWarning: \n",
      "5 fits failed out of a total of 5.\n",
      "The score on these train-test partitions for these parameters will be set to nan.\n",
      "If these failures are not expected, you can try to debug them by setting error_score='raise'.\n",
      "\n",
      "Below are more details about the failures:\n",
      "--------------------------------------------------------------------------------\n",
      "5 fits failed with the following error:\n",
      "Traceback (most recent call last):\n",
      "  File \"D:\\anaconda1\\lib\\site-packages\\sklearn\\model_selection\\_validation.py\", line 680, in _fit_and_score\n",
      "    estimator.fit(X_train, y_train, **fit_params)\n",
      "  File \"D:\\anaconda1\\lib\\site-packages\\sklearn\\ensemble\\_forest.py\", line 450, in fit\n",
      "    trees = Parallel(\n",
      "  File \"D:\\anaconda1\\lib\\site-packages\\joblib\\parallel.py\", line 1056, in __call__\n",
      "  File \"D:\\anaconda1\\lib\\site-packages\\joblib\\parallel.py\", line 935, in retrieve\n",
      "    Read more in the :ref:`User Guide <parallel>`.\n",
      "  File \"D:\\anaconda1\\lib\\site-packages\\joblib\\_parallel_backends.py\", line 542, in wrap_future_result\n",
      "    def configure(self, n_jobs=1, parallel=None, prefer=None, require=None,\n",
      "  File \"D:\\anaconda1\\lib\\concurrent\\futures\\_base.py\", line 446, in result\n",
      "    return self.__get_result()\n",
      "  File \"D:\\anaconda1\\lib\\concurrent\\futures\\_base.py\", line 391, in __get_result\n",
      "    raise self._exception\n",
      "  File \"D:\\anaconda1\\lib\\site-packages\\joblib\\externals\\loky\\_base.py\", line 625, in _invoke_callbacks\n",
      "  File \"D:\\anaconda1\\lib\\site-packages\\joblib\\parallel.py\", line 359, in __call__\n",
      "    **backend_params\n",
      "  File \"D:\\anaconda1\\lib\\site-packages\\joblib\\parallel.py\", line 794, in dispatch_next\n",
      "    # registers the task outcome (TASK_ERROR or TASK_DONE), and schedules\n",
      "  File \"D:\\anaconda1\\lib\\site-packages\\joblib\\parallel.py\", line 861, in dispatch_one_batch\n",
      "    with self.parallel._lock:\n",
      "  File \"D:\\anaconda1\\lib\\site-packages\\joblib\\parallel.py\", line 779, in _dispatch\n",
      "  File \"D:\\anaconda1\\lib\\site-packages\\joblib\\_parallel_backends.py\", line 531, in apply_async\n",
      "    \"\"\"Shutdown the process or thread pool\"\"\"\n",
      "  File \"D:\\anaconda1\\lib\\site-packages\\joblib\\externals\\loky\\reusable_executor.py\", line 177, in submit\n",
      "    mp.util.debug(\n",
      "  File \"D:\\anaconda1\\lib\\site-packages\\joblib\\externals\\loky\\process_executor.py\", line 1115, in submit\n",
      "    # of the main loop of executor_manager_thread from another thread (e.g.\n",
      "joblib.externals.loky.process_executor.TerminatedWorkerError: A worker process managed by the executor was unexpectedly terminated. This could be caused by a segmentation fault while calling the function or by an excessive memory usage causing the Operating System to kill the worker.\n",
      "\n",
      "\n"
     ]
    },
    {
     "name": "stdout",
     "output_type": "stream",
     "text": [
      "Cross-validation scores for Kavrepalanchok: [nan nan nan nan nan]\n",
      "Mean cross-validation accuracy for Kavrepalanchok: nan\n",
      "Accuracy of Kavrepalanchok: 0.42\n"
     ]
    },
    {
     "name": "stderr",
     "output_type": "stream",
     "text": [
      "exception calling callback for <Future at 0x25704430c70 state=finished raised TerminatedWorkerError>\n",
      "Traceback (most recent call last):\n",
      "  File \"D:\\anaconda1\\lib\\site-packages\\joblib\\externals\\loky\\_base.py\", line 625, in _invoke_callbacks\n",
      "  File \"D:\\anaconda1\\lib\\site-packages\\joblib\\parallel.py\", line 359, in __call__\n",
      "    **backend_params\n",
      "  File \"D:\\anaconda1\\lib\\site-packages\\joblib\\parallel.py\", line 794, in dispatch_next\n",
      "    # registers the task outcome (TASK_ERROR or TASK_DONE), and schedules\n",
      "  File \"D:\\anaconda1\\lib\\site-packages\\joblib\\parallel.py\", line 861, in dispatch_one_batch\n",
      "    with self.parallel._lock:\n",
      "  File \"D:\\anaconda1\\lib\\site-packages\\joblib\\parallel.py\", line 779, in _dispatch\n",
      "  File \"D:\\anaconda1\\lib\\site-packages\\joblib\\_parallel_backends.py\", line 531, in apply_async\n",
      "    \"\"\"Shutdown the process or thread pool\"\"\"\n",
      "  File \"D:\\anaconda1\\lib\\site-packages\\joblib\\externals\\loky\\reusable_executor.py\", line 177, in submit\n",
      "    mp.util.debug(\n",
      "  File \"D:\\anaconda1\\lib\\site-packages\\joblib\\externals\\loky\\process_executor.py\", line 1115, in submit\n",
      "    # of the main loop of executor_manager_thread from another thread (e.g.\n",
      "joblib.externals.loky.process_executor.TerminatedWorkerError: A worker process managed by the executor was unexpectedly terminated. This could be caused by a segmentation fault while calling the function or by an excessive memory usage causing the Operating System to kill the worker.\n",
      "\n",
      "exception calling callback for <Future at 0x257045c38b0 state=finished raised TerminatedWorkerError>\n",
      "Traceback (most recent call last):\n",
      "  File \"D:\\anaconda1\\lib\\site-packages\\joblib\\externals\\loky\\_base.py\", line 625, in _invoke_callbacks\n",
      "  File \"D:\\anaconda1\\lib\\site-packages\\joblib\\parallel.py\", line 359, in __call__\n",
      "    **backend_params\n",
      "  File \"D:\\anaconda1\\lib\\site-packages\\joblib\\parallel.py\", line 794, in dispatch_next\n",
      "    # registers the task outcome (TASK_ERROR or TASK_DONE), and schedules\n",
      "  File \"D:\\anaconda1\\lib\\site-packages\\joblib\\parallel.py\", line 861, in dispatch_one_batch\n",
      "    with self.parallel._lock:\n",
      "  File \"D:\\anaconda1\\lib\\site-packages\\joblib\\parallel.py\", line 779, in _dispatch\n",
      "  File \"D:\\anaconda1\\lib\\site-packages\\joblib\\_parallel_backends.py\", line 531, in apply_async\n",
      "    \"\"\"Shutdown the process or thread pool\"\"\"\n",
      "  File \"D:\\anaconda1\\lib\\site-packages\\joblib\\externals\\loky\\reusable_executor.py\", line 177, in submit\n",
      "    mp.util.debug(\n",
      "  File \"D:\\anaconda1\\lib\\site-packages\\joblib\\externals\\loky\\process_executor.py\", line 1115, in submit\n",
      "    # of the main loop of executor_manager_thread from another thread (e.g.\n",
      "joblib.externals.loky.process_executor.TerminatedWorkerError: A worker process managed by the executor was unexpectedly terminated. This could be caused by a segmentation fault while calling the function or by an excessive memory usage causing the Operating System to kill the worker.\n",
      "\n",
      "exception calling callback for <Future at 0x257045df7f0 state=finished raised TerminatedWorkerError>\n",
      "Traceback (most recent call last):\n",
      "  File \"D:\\anaconda1\\lib\\site-packages\\joblib\\externals\\loky\\_base.py\", line 625, in _invoke_callbacks\n",
      "  File \"D:\\anaconda1\\lib\\site-packages\\joblib\\parallel.py\", line 359, in __call__\n",
      "    **backend_params\n",
      "  File \"D:\\anaconda1\\lib\\site-packages\\joblib\\parallel.py\", line 794, in dispatch_next\n",
      "    # registers the task outcome (TASK_ERROR or TASK_DONE), and schedules\n",
      "  File \"D:\\anaconda1\\lib\\site-packages\\joblib\\parallel.py\", line 861, in dispatch_one_batch\n",
      "    with self.parallel._lock:\n",
      "  File \"D:\\anaconda1\\lib\\site-packages\\joblib\\parallel.py\", line 779, in _dispatch\n",
      "  File \"D:\\anaconda1\\lib\\site-packages\\joblib\\_parallel_backends.py\", line 531, in apply_async\n",
      "    \"\"\"Shutdown the process or thread pool\"\"\"\n",
      "  File \"D:\\anaconda1\\lib\\site-packages\\joblib\\externals\\loky\\reusable_executor.py\", line 177, in submit\n",
      "    mp.util.debug(\n",
      "  File \"D:\\anaconda1\\lib\\site-packages\\joblib\\externals\\loky\\process_executor.py\", line 1115, in submit\n",
      "    # of the main loop of executor_manager_thread from another thread (e.g.\n",
      "joblib.externals.loky.process_executor.TerminatedWorkerError: A worker process managed by the executor was unexpectedly terminated. This could be caused by a segmentation fault while calling the function or by an excessive memory usage causing the Operating System to kill the worker.\n",
      "\n",
      "exception calling callback for <Future at 0x257045e15e0 state=finished raised TerminatedWorkerError>\n",
      "Traceback (most recent call last):\n",
      "  File \"D:\\anaconda1\\lib\\site-packages\\joblib\\externals\\loky\\_base.py\", line 625, in _invoke_callbacks\n",
      "  File \"D:\\anaconda1\\lib\\site-packages\\joblib\\parallel.py\", line 359, in __call__\n",
      "    **backend_params\n",
      "  File \"D:\\anaconda1\\lib\\site-packages\\joblib\\parallel.py\", line 794, in dispatch_next\n",
      "    # registers the task outcome (TASK_ERROR or TASK_DONE), and schedules\n",
      "  File \"D:\\anaconda1\\lib\\site-packages\\joblib\\parallel.py\", line 861, in dispatch_one_batch\n",
      "    with self.parallel._lock:\n",
      "  File \"D:\\anaconda1\\lib\\site-packages\\joblib\\parallel.py\", line 779, in _dispatch\n",
      "  File \"D:\\anaconda1\\lib\\site-packages\\joblib\\_parallel_backends.py\", line 531, in apply_async\n",
      "    \"\"\"Shutdown the process or thread pool\"\"\"\n",
      "  File \"D:\\anaconda1\\lib\\site-packages\\joblib\\externals\\loky\\reusable_executor.py\", line 177, in submit\n",
      "    mp.util.debug(\n",
      "  File \"D:\\anaconda1\\lib\\site-packages\\joblib\\externals\\loky\\process_executor.py\", line 1115, in submit\n",
      "    # of the main loop of executor_manager_thread from another thread (e.g.\n",
      "joblib.externals.loky.process_executor.TerminatedWorkerError: A worker process managed by the executor was unexpectedly terminated. This could be caused by a segmentation fault while calling the function or by an excessive memory usage causing the Operating System to kill the worker.\n",
      "\n",
      "exception calling callback for <Future at 0x257045f4a00 state=finished raised TerminatedWorkerError>\n",
      "Traceback (most recent call last):\n",
      "  File \"D:\\anaconda1\\lib\\site-packages\\joblib\\externals\\loky\\_base.py\", line 625, in _invoke_callbacks\n",
      "  File \"D:\\anaconda1\\lib\\site-packages\\joblib\\parallel.py\", line 359, in __call__\n",
      "    **backend_params\n",
      "  File \"D:\\anaconda1\\lib\\site-packages\\joblib\\parallel.py\", line 794, in dispatch_next\n",
      "    # registers the task outcome (TASK_ERROR or TASK_DONE), and schedules\n",
      "  File \"D:\\anaconda1\\lib\\site-packages\\joblib\\parallel.py\", line 861, in dispatch_one_batch\n",
      "    with self.parallel._lock:\n",
      "  File \"D:\\anaconda1\\lib\\site-packages\\joblib\\parallel.py\", line 779, in _dispatch\n",
      "  File \"D:\\anaconda1\\lib\\site-packages\\joblib\\_parallel_backends.py\", line 531, in apply_async\n",
      "    \"\"\"Shutdown the process or thread pool\"\"\"\n",
      "  File \"D:\\anaconda1\\lib\\site-packages\\joblib\\externals\\loky\\reusable_executor.py\", line 177, in submit\n",
      "    mp.util.debug(\n",
      "  File \"D:\\anaconda1\\lib\\site-packages\\joblib\\externals\\loky\\process_executor.py\", line 1115, in submit\n",
      "    # of the main loop of executor_manager_thread from another thread (e.g.\n",
      "joblib.externals.loky.process_executor.TerminatedWorkerError: A worker process managed by the executor was unexpectedly terminated. This could be caused by a segmentation fault while calling the function or by an excessive memory usage causing the Operating System to kill the worker.\n",
      "\n",
      "D:\\anaconda1\\lib\\site-packages\\sklearn\\model_selection\\_validation.py:372: FitFailedWarning: \n",
      "5 fits failed out of a total of 5.\n",
      "The score on these train-test partitions for these parameters will be set to nan.\n",
      "If these failures are not expected, you can try to debug them by setting error_score='raise'.\n",
      "\n",
      "Below are more details about the failures:\n",
      "--------------------------------------------------------------------------------\n",
      "5 fits failed with the following error:\n",
      "Traceback (most recent call last):\n",
      "  File \"D:\\anaconda1\\lib\\site-packages\\sklearn\\model_selection\\_validation.py\", line 680, in _fit_and_score\n",
      "    estimator.fit(X_train, y_train, **fit_params)\n",
      "  File \"D:\\anaconda1\\lib\\site-packages\\sklearn\\ensemble\\_forest.py\", line 450, in fit\n",
      "    trees = Parallel(\n",
      "  File \"D:\\anaconda1\\lib\\site-packages\\joblib\\parallel.py\", line 1056, in __call__\n",
      "  File \"D:\\anaconda1\\lib\\site-packages\\joblib\\parallel.py\", line 935, in retrieve\n",
      "    Read more in the :ref:`User Guide <parallel>`.\n",
      "  File \"D:\\anaconda1\\lib\\site-packages\\joblib\\_parallel_backends.py\", line 542, in wrap_future_result\n",
      "    def configure(self, n_jobs=1, parallel=None, prefer=None, require=None,\n",
      "  File \"D:\\anaconda1\\lib\\concurrent\\futures\\_base.py\", line 446, in result\n",
      "    return self.__get_result()\n",
      "  File \"D:\\anaconda1\\lib\\concurrent\\futures\\_base.py\", line 391, in __get_result\n",
      "    raise self._exception\n",
      "  File \"D:\\anaconda1\\lib\\site-packages\\joblib\\externals\\loky\\_base.py\", line 625, in _invoke_callbacks\n",
      "  File \"D:\\anaconda1\\lib\\site-packages\\joblib\\parallel.py\", line 359, in __call__\n",
      "    **backend_params\n",
      "  File \"D:\\anaconda1\\lib\\site-packages\\joblib\\parallel.py\", line 794, in dispatch_next\n",
      "    # registers the task outcome (TASK_ERROR or TASK_DONE), and schedules\n",
      "  File \"D:\\anaconda1\\lib\\site-packages\\joblib\\parallel.py\", line 861, in dispatch_one_batch\n",
      "    with self.parallel._lock:\n",
      "  File \"D:\\anaconda1\\lib\\site-packages\\joblib\\parallel.py\", line 779, in _dispatch\n",
      "  File \"D:\\anaconda1\\lib\\site-packages\\joblib\\_parallel_backends.py\", line 531, in apply_async\n",
      "    \"\"\"Shutdown the process or thread pool\"\"\"\n",
      "  File \"D:\\anaconda1\\lib\\site-packages\\joblib\\externals\\loky\\reusable_executor.py\", line 177, in submit\n",
      "    mp.util.debug(\n",
      "  File \"D:\\anaconda1\\lib\\site-packages\\joblib\\externals\\loky\\process_executor.py\", line 1115, in submit\n",
      "    # of the main loop of executor_manager_thread from another thread (e.g.\n",
      "joblib.externals.loky.process_executor.TerminatedWorkerError: A worker process managed by the executor was unexpectedly terminated. This could be caused by a segmentation fault while calling the function or by an excessive memory usage causing the Operating System to kill the worker.\n",
      "\n",
      "\n"
     ]
    },
    {
     "name": "stdout",
     "output_type": "stream",
     "text": [
      "Cross-validation scores for Makwanpur: [nan nan nan nan nan]\n",
      "Mean cross-validation accuracy for Makwanpur: nan\n",
      "Accuracy of Makwanpur: 0.36\n"
     ]
    },
    {
     "name": "stderr",
     "output_type": "stream",
     "text": [
      "exception calling callback for <Future at 0x25704611820 state=finished raised TerminatedWorkerError>\n",
      "Traceback (most recent call last):\n",
      "  File \"D:\\anaconda1\\lib\\site-packages\\joblib\\externals\\loky\\_base.py\", line 625, in _invoke_callbacks\n",
      "  File \"D:\\anaconda1\\lib\\site-packages\\joblib\\parallel.py\", line 359, in __call__\n",
      "    **backend_params\n",
      "  File \"D:\\anaconda1\\lib\\site-packages\\joblib\\parallel.py\", line 794, in dispatch_next\n",
      "    # registers the task outcome (TASK_ERROR or TASK_DONE), and schedules\n",
      "  File \"D:\\anaconda1\\lib\\site-packages\\joblib\\parallel.py\", line 861, in dispatch_one_batch\n",
      "    with self.parallel._lock:\n",
      "  File \"D:\\anaconda1\\lib\\site-packages\\joblib\\parallel.py\", line 779, in _dispatch\n",
      "  File \"D:\\anaconda1\\lib\\site-packages\\joblib\\_parallel_backends.py\", line 531, in apply_async\n",
      "    \"\"\"Shutdown the process or thread pool\"\"\"\n",
      "  File \"D:\\anaconda1\\lib\\site-packages\\joblib\\externals\\loky\\reusable_executor.py\", line 177, in submit\n",
      "    mp.util.debug(\n",
      "  File \"D:\\anaconda1\\lib\\site-packages\\joblib\\externals\\loky\\process_executor.py\", line 1115, in submit\n",
      "    # of the main loop of executor_manager_thread from another thread (e.g.\n",
      "joblib.externals.loky.process_executor.TerminatedWorkerError: A worker process managed by the executor was unexpectedly terminated. This could be caused by a segmentation fault while calling the function or by an excessive memory usage causing the Operating System to kill the worker.\n",
      "\n",
      "exception calling callback for <Future at 0x257046146a0 state=finished raised TerminatedWorkerError>\n",
      "Traceback (most recent call last):\n",
      "  File \"D:\\anaconda1\\lib\\site-packages\\joblib\\externals\\loky\\_base.py\", line 625, in _invoke_callbacks\n",
      "  File \"D:\\anaconda1\\lib\\site-packages\\joblib\\parallel.py\", line 359, in __call__\n",
      "    **backend_params\n",
      "  File \"D:\\anaconda1\\lib\\site-packages\\joblib\\parallel.py\", line 794, in dispatch_next\n",
      "    # registers the task outcome (TASK_ERROR or TASK_DONE), and schedules\n",
      "  File \"D:\\anaconda1\\lib\\site-packages\\joblib\\parallel.py\", line 861, in dispatch_one_batch\n",
      "    with self.parallel._lock:\n",
      "  File \"D:\\anaconda1\\lib\\site-packages\\joblib\\parallel.py\", line 779, in _dispatch\n",
      "  File \"D:\\anaconda1\\lib\\site-packages\\joblib\\_parallel_backends.py\", line 531, in apply_async\n",
      "    \"\"\"Shutdown the process or thread pool\"\"\"\n",
      "  File \"D:\\anaconda1\\lib\\site-packages\\joblib\\externals\\loky\\reusable_executor.py\", line 177, in submit\n",
      "    mp.util.debug(\n",
      "  File \"D:\\anaconda1\\lib\\site-packages\\joblib\\externals\\loky\\process_executor.py\", line 1115, in submit\n",
      "    # of the main loop of executor_manager_thread from another thread (e.g.\n",
      "joblib.externals.loky.process_executor.TerminatedWorkerError: A worker process managed by the executor was unexpectedly terminated. This could be caused by a segmentation fault while calling the function or by an excessive memory usage causing the Operating System to kill the worker.\n",
      "\n",
      "exception calling callback for <Future at 0x257045a53d0 state=finished raised TerminatedWorkerError>\n",
      "Traceback (most recent call last):\n",
      "  File \"D:\\anaconda1\\lib\\site-packages\\joblib\\externals\\loky\\_base.py\", line 625, in _invoke_callbacks\n",
      "  File \"D:\\anaconda1\\lib\\site-packages\\joblib\\parallel.py\", line 359, in __call__\n",
      "    **backend_params\n",
      "  File \"D:\\anaconda1\\lib\\site-packages\\joblib\\parallel.py\", line 794, in dispatch_next\n",
      "    # registers the task outcome (TASK_ERROR or TASK_DONE), and schedules\n",
      "  File \"D:\\anaconda1\\lib\\site-packages\\joblib\\parallel.py\", line 861, in dispatch_one_batch\n",
      "    with self.parallel._lock:\n",
      "  File \"D:\\anaconda1\\lib\\site-packages\\joblib\\parallel.py\", line 779, in _dispatch\n",
      "  File \"D:\\anaconda1\\lib\\site-packages\\joblib\\_parallel_backends.py\", line 531, in apply_async\n",
      "    \"\"\"Shutdown the process or thread pool\"\"\"\n",
      "  File \"D:\\anaconda1\\lib\\site-packages\\joblib\\externals\\loky\\reusable_executor.py\", line 177, in submit\n",
      "    mp.util.debug(\n",
      "  File \"D:\\anaconda1\\lib\\site-packages\\joblib\\externals\\loky\\process_executor.py\", line 1115, in submit\n",
      "    # of the main loop of executor_manager_thread from another thread (e.g.\n",
      "joblib.externals.loky.process_executor.TerminatedWorkerError: A worker process managed by the executor was unexpectedly terminated. This could be caused by a segmentation fault while calling the function or by an excessive memory usage causing the Operating System to kill the worker.\n",
      "\n",
      "exception calling callback for <Future at 0x25703567b80 state=finished raised TerminatedWorkerError>\n",
      "Traceback (most recent call last):\n",
      "  File \"D:\\anaconda1\\lib\\site-packages\\joblib\\externals\\loky\\_base.py\", line 625, in _invoke_callbacks\n",
      "  File \"D:\\anaconda1\\lib\\site-packages\\joblib\\parallel.py\", line 359, in __call__\n",
      "    **backend_params\n",
      "  File \"D:\\anaconda1\\lib\\site-packages\\joblib\\parallel.py\", line 794, in dispatch_next\n",
      "    # registers the task outcome (TASK_ERROR or TASK_DONE), and schedules\n",
      "  File \"D:\\anaconda1\\lib\\site-packages\\joblib\\parallel.py\", line 861, in dispatch_one_batch\n",
      "    with self.parallel._lock:\n",
      "  File \"D:\\anaconda1\\lib\\site-packages\\joblib\\parallel.py\", line 779, in _dispatch\n",
      "  File \"D:\\anaconda1\\lib\\site-packages\\joblib\\_parallel_backends.py\", line 531, in apply_async\n",
      "    \"\"\"Shutdown the process or thread pool\"\"\"\n",
      "  File \"D:\\anaconda1\\lib\\site-packages\\joblib\\externals\\loky\\reusable_executor.py\", line 177, in submit\n",
      "    mp.util.debug(\n",
      "  File \"D:\\anaconda1\\lib\\site-packages\\joblib\\externals\\loky\\process_executor.py\", line 1115, in submit\n",
      "    # of the main loop of executor_manager_thread from another thread (e.g.\n",
      "joblib.externals.loky.process_executor.TerminatedWorkerError: A worker process managed by the executor was unexpectedly terminated. This could be caused by a segmentation fault while calling the function or by an excessive memory usage causing the Operating System to kill the worker.\n",
      "\n",
      "exception calling callback for <Future at 0x25704660a30 state=finished raised TerminatedWorkerError>\n",
      "Traceback (most recent call last):\n",
      "  File \"D:\\anaconda1\\lib\\site-packages\\joblib\\externals\\loky\\_base.py\", line 625, in _invoke_callbacks\n",
      "  File \"D:\\anaconda1\\lib\\site-packages\\joblib\\parallel.py\", line 359, in __call__\n",
      "    **backend_params\n",
      "  File \"D:\\anaconda1\\lib\\site-packages\\joblib\\parallel.py\", line 794, in dispatch_next\n",
      "    # registers the task outcome (TASK_ERROR or TASK_DONE), and schedules\n",
      "  File \"D:\\anaconda1\\lib\\site-packages\\joblib\\parallel.py\", line 861, in dispatch_one_batch\n",
      "    with self.parallel._lock:\n",
      "  File \"D:\\anaconda1\\lib\\site-packages\\joblib\\parallel.py\", line 779, in _dispatch\n",
      "  File \"D:\\anaconda1\\lib\\site-packages\\joblib\\_parallel_backends.py\", line 531, in apply_async\n",
      "    \"\"\"Shutdown the process or thread pool\"\"\"\n",
      "  File \"D:\\anaconda1\\lib\\site-packages\\joblib\\externals\\loky\\reusable_executor.py\", line 177, in submit\n",
      "    mp.util.debug(\n",
      "  File \"D:\\anaconda1\\lib\\site-packages\\joblib\\externals\\loky\\process_executor.py\", line 1115, in submit\n",
      "    # of the main loop of executor_manager_thread from another thread (e.g.\n",
      "joblib.externals.loky.process_executor.TerminatedWorkerError: A worker process managed by the executor was unexpectedly terminated. This could be caused by a segmentation fault while calling the function or by an excessive memory usage causing the Operating System to kill the worker.\n",
      "\n",
      "exception calling callback for <Future at 0x25704665340 state=finished raised TerminatedWorkerError>\n",
      "Traceback (most recent call last):\n",
      "  File \"D:\\anaconda1\\lib\\site-packages\\joblib\\externals\\loky\\_base.py\", line 625, in _invoke_callbacks\n",
      "  File \"D:\\anaconda1\\lib\\site-packages\\joblib\\parallel.py\", line 359, in __call__\n",
      "    **backend_params\n",
      "  File \"D:\\anaconda1\\lib\\site-packages\\joblib\\parallel.py\", line 794, in dispatch_next\n",
      "    # registers the task outcome (TASK_ERROR or TASK_DONE), and schedules\n",
      "  File \"D:\\anaconda1\\lib\\site-packages\\joblib\\parallel.py\", line 861, in dispatch_one_batch\n",
      "    with self.parallel._lock:\n",
      "  File \"D:\\anaconda1\\lib\\site-packages\\joblib\\parallel.py\", line 779, in _dispatch\n",
      "  File \"D:\\anaconda1\\lib\\site-packages\\joblib\\_parallel_backends.py\", line 531, in apply_async\n",
      "    \"\"\"Shutdown the process or thread pool\"\"\"\n",
      "  File \"D:\\anaconda1\\lib\\site-packages\\joblib\\externals\\loky\\reusable_executor.py\", line 177, in submit\n",
      "    mp.util.debug(\n",
      "  File \"D:\\anaconda1\\lib\\site-packages\\joblib\\externals\\loky\\process_executor.py\", line 1115, in submit\n",
      "    # of the main loop of executor_manager_thread from another thread (e.g.\n",
      "  File \"D:\\anaconda1\\lib\\site-packages\\joblib\\externals\\loky\\_base.py\", line 625, in _invoke_callbacks\n",
      "  File \"D:\\anaconda1\\lib\\site-packages\\joblib\\parallel.py\", line 359, in __call__\n",
      "    **backend_params\n",
      "  File \"D:\\anaconda1\\lib\\site-packages\\joblib\\parallel.py\", line 794, in dispatch_next\n",
      "    # registers the task outcome (TASK_ERROR or TASK_DONE), and schedules\n",
      "  File \"D:\\anaconda1\\lib\\site-packages\\joblib\\parallel.py\", line 861, in dispatch_one_batch\n",
      "    with self.parallel._lock:\n",
      "  File \"D:\\anaconda1\\lib\\site-packages\\joblib\\parallel.py\", line 779, in _dispatch\n",
      "  File \"D:\\anaconda1\\lib\\site-packages\\joblib\\_parallel_backends.py\", line 531, in apply_async\n",
      "    \"\"\"Shutdown the process or thread pool\"\"\"\n",
      "  File \"D:\\anaconda1\\lib\\site-packages\\joblib\\externals\\loky\\reusable_executor.py\", line 177, in submit\n",
      "    mp.util.debug(\n",
      "  File \"D:\\anaconda1\\lib\\site-packages\\joblib\\externals\\loky\\process_executor.py\", line 1115, in submit\n",
      "    # of the main loop of executor_manager_thread from another thread (e.g.\n",
      "joblib.externals.loky.process_executor.TerminatedWorkerError: A worker process managed by the executor was unexpectedly terminated. This could be caused by a segmentation fault while calling the function or by an excessive memory usage causing the Operating System to kill the worker.\n",
      "\n"
     ]
    },
    {
     "name": "stderr",
     "output_type": "stream",
     "text": [
      "D:\\anaconda1\\lib\\site-packages\\sklearn\\model_selection\\_validation.py:372: FitFailedWarning: \n",
      "5 fits failed out of a total of 5.\n",
      "The score on these train-test partitions for these parameters will be set to nan.\n",
      "If these failures are not expected, you can try to debug them by setting error_score='raise'.\n",
      "\n",
      "Below are more details about the failures:\n",
      "--------------------------------------------------------------------------------\n",
      "4 fits failed with the following error:\n",
      "Traceback (most recent call last):\n",
      "  File \"D:\\anaconda1\\lib\\site-packages\\sklearn\\model_selection\\_validation.py\", line 680, in _fit_and_score\n",
      "    estimator.fit(X_train, y_train, **fit_params)\n",
      "  File \"D:\\anaconda1\\lib\\site-packages\\sklearn\\ensemble\\_forest.py\", line 450, in fit\n",
      "    trees = Parallel(\n",
      "  File \"D:\\anaconda1\\lib\\site-packages\\joblib\\parallel.py\", line 1056, in __call__\n",
      "  File \"D:\\anaconda1\\lib\\site-packages\\joblib\\parallel.py\", line 935, in retrieve\n",
      "    Read more in the :ref:`User Guide <parallel>`.\n",
      "  File \"D:\\anaconda1\\lib\\site-packages\\joblib\\_parallel_backends.py\", line 542, in wrap_future_result\n",
      "    def configure(self, n_jobs=1, parallel=None, prefer=None, require=None,\n",
      "  File \"D:\\anaconda1\\lib\\concurrent\\futures\\_base.py\", line 446, in result\n",
      "    return self.__get_result()\n",
      "  File \"D:\\anaconda1\\lib\\concurrent\\futures\\_base.py\", line 391, in __get_result\n",
      "    raise self._exception\n",
      "  File \"D:\\anaconda1\\lib\\site-packages\\joblib\\externals\\loky\\_base.py\", line 625, in _invoke_callbacks\n",
      "  File \"D:\\anaconda1\\lib\\site-packages\\joblib\\parallel.py\", line 359, in __call__\n",
      "    **backend_params\n",
      "  File \"D:\\anaconda1\\lib\\site-packages\\joblib\\parallel.py\", line 794, in dispatch_next\n",
      "    # registers the task outcome (TASK_ERROR or TASK_DONE), and schedules\n",
      "  File \"D:\\anaconda1\\lib\\site-packages\\joblib\\parallel.py\", line 861, in dispatch_one_batch\n",
      "    with self.parallel._lock:\n",
      "  File \"D:\\anaconda1\\lib\\site-packages\\joblib\\parallel.py\", line 779, in _dispatch\n",
      "  File \"D:\\anaconda1\\lib\\site-packages\\joblib\\_parallel_backends.py\", line 531, in apply_async\n",
      "    \"\"\"Shutdown the process or thread pool\"\"\"\n",
      "  File \"D:\\anaconda1\\lib\\site-packages\\joblib\\externals\\loky\\reusable_executor.py\", line 177, in submit\n",
      "    mp.util.debug(\n",
      "  File \"D:\\anaconda1\\lib\\site-packages\\joblib\\externals\\loky\\process_executor.py\", line 1115, in submit\n",
      "    # of the main loop of executor_manager_thread from another thread (e.g.\n",
      "joblib.externals.loky.process_executor.TerminatedWorkerError: A worker process managed by the executor was unexpectedly terminated. This could be caused by a segmentation fault while calling the function or by an excessive memory usage causing the Operating System to kill the worker.\n",
      "\n",
      "\n",
      "--------------------------------------------------------------------------------\n",
      "1 fits failed with the following error:\n",
      "Traceback (most recent call last):\n",
      "  File \"D:\\anaconda1\\lib\\site-packages\\sklearn\\model_selection\\_validation.py\", line 680, in _fit_and_score\n",
      "    estimator.fit(X_train, y_train, **fit_params)\n",
      "  File \"D:\\anaconda1\\lib\\site-packages\\sklearn\\ensemble\\_forest.py\", line 450, in fit\n",
      "    trees = Parallel(\n",
      "  File \"D:\\anaconda1\\lib\\site-packages\\joblib\\parallel.py\", line 1056, in __call__\n",
      "  File \"D:\\anaconda1\\lib\\site-packages\\joblib\\parallel.py\", line 935, in retrieve\n",
      "    Read more in the :ref:`User Guide <parallel>`.\n",
      "  File \"D:\\anaconda1\\lib\\site-packages\\joblib\\_parallel_backends.py\", line 542, in wrap_future_result\n",
      "    def configure(self, n_jobs=1, parallel=None, prefer=None, require=None,\n",
      "  File \"D:\\anaconda1\\lib\\concurrent\\futures\\_base.py\", line 446, in result\n",
      "    return self.__get_result()\n",
      "  File \"D:\\anaconda1\\lib\\concurrent\\futures\\_base.py\", line 391, in __get_result\n",
      "    raise self._exception\n",
      "  File \"D:\\anaconda1\\lib\\site-packages\\joblib\\externals\\loky\\_base.py\", line 625, in _invoke_callbacks\n",
      "  File \"D:\\anaconda1\\lib\\site-packages\\joblib\\parallel.py\", line 359, in __call__\n",
      "    **backend_params\n",
      "  File \"D:\\anaconda1\\lib\\site-packages\\joblib\\parallel.py\", line 794, in dispatch_next\n",
      "    # registers the task outcome (TASK_ERROR or TASK_DONE), and schedules\n",
      "  File \"D:\\anaconda1\\lib\\site-packages\\joblib\\parallel.py\", line 861, in dispatch_one_batch\n",
      "    with self.parallel._lock:\n",
      "  File \"D:\\anaconda1\\lib\\site-packages\\joblib\\parallel.py\", line 779, in _dispatch\n",
      "  File \"D:\\anaconda1\\lib\\site-packages\\joblib\\_parallel_backends.py\", line 531, in apply_async\n",
      "    \"\"\"Shutdown the process or thread pool\"\"\"\n",
      "  File \"D:\\anaconda1\\lib\\site-packages\\joblib\\externals\\loky\\reusable_executor.py\", line 177, in submit\n",
      "    mp.util.debug(\n",
      "  File \"D:\\anaconda1\\lib\\site-packages\\joblib\\externals\\loky\\process_executor.py\", line 1115, in submit\n",
      "    # of the main loop of executor_manager_thread from another thread (e.g.\n",
      "  File \"D:\\anaconda1\\lib\\site-packages\\joblib\\externals\\loky\\_base.py\", line 625, in _invoke_callbacks\n",
      "  File \"D:\\anaconda1\\lib\\site-packages\\joblib\\parallel.py\", line 359, in __call__\n",
      "    **backend_params\n",
      "  File \"D:\\anaconda1\\lib\\site-packages\\joblib\\parallel.py\", line 794, in dispatch_next\n",
      "    # registers the task outcome (TASK_ERROR or TASK_DONE), and schedules\n",
      "  File \"D:\\anaconda1\\lib\\site-packages\\joblib\\parallel.py\", line 861, in dispatch_one_batch\n",
      "    with self.parallel._lock:\n",
      "  File \"D:\\anaconda1\\lib\\site-packages\\joblib\\parallel.py\", line 779, in _dispatch\n",
      "  File \"D:\\anaconda1\\lib\\site-packages\\joblib\\_parallel_backends.py\", line 531, in apply_async\n",
      "    \"\"\"Shutdown the process or thread pool\"\"\"\n",
      "  File \"D:\\anaconda1\\lib\\site-packages\\joblib\\externals\\loky\\reusable_executor.py\", line 177, in submit\n",
      "    mp.util.debug(\n",
      "  File \"D:\\anaconda1\\lib\\site-packages\\joblib\\externals\\loky\\process_executor.py\", line 1115, in submit\n",
      "    # of the main loop of executor_manager_thread from another thread (e.g.\n",
      "joblib.externals.loky.process_executor.TerminatedWorkerError: A worker process managed by the executor was unexpectedly terminated. This could be caused by a segmentation fault while calling the function or by an excessive memory usage causing the Operating System to kill the worker.\n",
      "\n",
      "\n"
     ]
    },
    {
     "name": "stdout",
     "output_type": "stream",
     "text": [
      "Cross-validation scores for Nuwakot: [nan nan nan nan nan]\n",
      "Mean cross-validation accuracy for Nuwakot: nan\n",
      "Accuracy of Nuwakot: 0.44\n"
     ]
    },
    {
     "name": "stderr",
     "output_type": "stream",
     "text": [
      "exception calling callback for <Future at 0x257046970a0 state=finished raised TerminatedWorkerError>\n",
      "Traceback (most recent call last):\n",
      "  File \"D:\\anaconda1\\lib\\site-packages\\joblib\\externals\\loky\\_base.py\", line 625, in _invoke_callbacks\n",
      "  File \"D:\\anaconda1\\lib\\site-packages\\joblib\\parallel.py\", line 359, in __call__\n",
      "    **backend_params\n",
      "  File \"D:\\anaconda1\\lib\\site-packages\\joblib\\parallel.py\", line 794, in dispatch_next\n",
      "    # registers the task outcome (TASK_ERROR or TASK_DONE), and schedules\n",
      "  File \"D:\\anaconda1\\lib\\site-packages\\joblib\\parallel.py\", line 861, in dispatch_one_batch\n",
      "    with self.parallel._lock:\n",
      "  File \"D:\\anaconda1\\lib\\site-packages\\joblib\\parallel.py\", line 779, in _dispatch\n",
      "  File \"D:\\anaconda1\\lib\\site-packages\\joblib\\_parallel_backends.py\", line 531, in apply_async\n",
      "    \"\"\"Shutdown the process or thread pool\"\"\"\n",
      "  File \"D:\\anaconda1\\lib\\site-packages\\joblib\\externals\\loky\\reusable_executor.py\", line 177, in submit\n",
      "    mp.util.debug(\n",
      "  File \"D:\\anaconda1\\lib\\site-packages\\joblib\\externals\\loky\\process_executor.py\", line 1115, in submit\n",
      "    # of the main loop of executor_manager_thread from another thread (e.g.\n",
      "joblib.externals.loky.process_executor.TerminatedWorkerError: A worker process managed by the executor was unexpectedly terminated. This could be caused by a segmentation fault while calling the function or by an excessive memory usage causing the Operating System to kill the worker.\n",
      "\n",
      "exception calling callback for <Future at 0x25704697d60 state=finished raised TerminatedWorkerError>\n",
      "Traceback (most recent call last):\n",
      "  File \"D:\\anaconda1\\lib\\site-packages\\joblib\\externals\\loky\\_base.py\", line 625, in _invoke_callbacks\n",
      "  File \"D:\\anaconda1\\lib\\site-packages\\joblib\\parallel.py\", line 359, in __call__\n",
      "    **backend_params\n",
      "  File \"D:\\anaconda1\\lib\\site-packages\\joblib\\parallel.py\", line 794, in dispatch_next\n",
      "    # registers the task outcome (TASK_ERROR or TASK_DONE), and schedules\n",
      "  File \"D:\\anaconda1\\lib\\site-packages\\joblib\\parallel.py\", line 861, in dispatch_one_batch\n",
      "    with self.parallel._lock:\n",
      "  File \"D:\\anaconda1\\lib\\site-packages\\joblib\\parallel.py\", line 779, in _dispatch\n",
      "  File \"D:\\anaconda1\\lib\\site-packages\\joblib\\_parallel_backends.py\", line 531, in apply_async\n",
      "    \"\"\"Shutdown the process or thread pool\"\"\"\n",
      "  File \"D:\\anaconda1\\lib\\site-packages\\joblib\\externals\\loky\\reusable_executor.py\", line 177, in submit\n",
      "    mp.util.debug(\n",
      "  File \"D:\\anaconda1\\lib\\site-packages\\joblib\\externals\\loky\\process_executor.py\", line 1115, in submit\n",
      "    # of the main loop of executor_manager_thread from another thread (e.g.\n",
      "  File \"D:\\anaconda1\\lib\\site-packages\\joblib\\externals\\loky\\_base.py\", line 625, in _invoke_callbacks\n",
      "  File \"D:\\anaconda1\\lib\\site-packages\\joblib\\parallel.py\", line 359, in __call__\n",
      "    **backend_params\n",
      "  File \"D:\\anaconda1\\lib\\site-packages\\joblib\\parallel.py\", line 794, in dispatch_next\n",
      "    # registers the task outcome (TASK_ERROR or TASK_DONE), and schedules\n",
      "  File \"D:\\anaconda1\\lib\\site-packages\\joblib\\parallel.py\", line 861, in dispatch_one_batch\n",
      "    with self.parallel._lock:\n",
      "  File \"D:\\anaconda1\\lib\\site-packages\\joblib\\parallel.py\", line 779, in _dispatch\n",
      "  File \"D:\\anaconda1\\lib\\site-packages\\joblib\\_parallel_backends.py\", line 531, in apply_async\n",
      "    \"\"\"Shutdown the process or thread pool\"\"\"\n",
      "  File \"D:\\anaconda1\\lib\\site-packages\\joblib\\externals\\loky\\reusable_executor.py\", line 177, in submit\n",
      "    mp.util.debug(\n",
      "  File \"D:\\anaconda1\\lib\\site-packages\\joblib\\externals\\loky\\process_executor.py\", line 1115, in submit\n",
      "    # of the main loop of executor_manager_thread from another thread (e.g.\n",
      "joblib.externals.loky.process_executor.TerminatedWorkerError: A worker process managed by the executor was unexpectedly terminated. This could be caused by a segmentation fault while calling the function or by an excessive memory usage causing the Operating System to kill the worker.\n",
      "\n",
      "exception calling callback for <Future at 0x25704697eb0 state=finished raised TerminatedWorkerError>\n",
      "Traceback (most recent call last):\n",
      "  File \"D:\\anaconda1\\lib\\site-packages\\joblib\\externals\\loky\\_base.py\", line 625, in _invoke_callbacks\n",
      "  File \"D:\\anaconda1\\lib\\site-packages\\joblib\\parallel.py\", line 359, in __call__\n",
      "    **backend_params\n",
      "  File \"D:\\anaconda1\\lib\\site-packages\\joblib\\parallel.py\", line 794, in dispatch_next\n",
      "    # registers the task outcome (TASK_ERROR or TASK_DONE), and schedules\n",
      "  File \"D:\\anaconda1\\lib\\site-packages\\joblib\\parallel.py\", line 861, in dispatch_one_batch\n",
      "    with self.parallel._lock:\n",
      "  File \"D:\\anaconda1\\lib\\site-packages\\joblib\\parallel.py\", line 779, in _dispatch\n",
      "  File \"D:\\anaconda1\\lib\\site-packages\\joblib\\_parallel_backends.py\", line 531, in apply_async\n",
      "    \"\"\"Shutdown the process or thread pool\"\"\"\n",
      "  File \"D:\\anaconda1\\lib\\site-packages\\joblib\\externals\\loky\\reusable_executor.py\", line 177, in submit\n",
      "    mp.util.debug(\n",
      "  File \"D:\\anaconda1\\lib\\site-packages\\joblib\\externals\\loky\\process_executor.py\", line 1115, in submit\n",
      "    # of the main loop of executor_manager_thread from another thread (e.g.\n",
      "  File \"D:\\anaconda1\\lib\\site-packages\\joblib\\externals\\loky\\_base.py\", line 625, in _invoke_callbacks\n",
      "  File \"D:\\anaconda1\\lib\\site-packages\\joblib\\parallel.py\", line 359, in __call__\n",
      "    **backend_params\n",
      "  File \"D:\\anaconda1\\lib\\site-packages\\joblib\\parallel.py\", line 794, in dispatch_next\n",
      "    # registers the task outcome (TASK_ERROR or TASK_DONE), and schedules\n",
      "  File \"D:\\anaconda1\\lib\\site-packages\\joblib\\parallel.py\", line 861, in dispatch_one_batch\n",
      "    with self.parallel._lock:\n",
      "  File \"D:\\anaconda1\\lib\\site-packages\\joblib\\parallel.py\", line 779, in _dispatch\n",
      "  File \"D:\\anaconda1\\lib\\site-packages\\joblib\\_parallel_backends.py\", line 531, in apply_async\n",
      "    \"\"\"Shutdown the process or thread pool\"\"\"\n",
      "  File \"D:\\anaconda1\\lib\\site-packages\\joblib\\externals\\loky\\reusable_executor.py\", line 177, in submit\n",
      "    mp.util.debug(\n",
      "  File \"D:\\anaconda1\\lib\\site-packages\\joblib\\externals\\loky\\process_executor.py\", line 1115, in submit\n",
      "    # of the main loop of executor_manager_thread from another thread (e.g.\n",
      "  File \"D:\\anaconda1\\lib\\site-packages\\joblib\\externals\\loky\\_base.py\", line 625, in _invoke_callbacks\n",
      "  File \"D:\\anaconda1\\lib\\site-packages\\joblib\\parallel.py\", line 359, in __call__\n",
      "    **backend_params\n",
      "  File \"D:\\anaconda1\\lib\\site-packages\\joblib\\parallel.py\", line 794, in dispatch_next\n",
      "    # registers the task outcome (TASK_ERROR or TASK_DONE), and schedules\n",
      "  File \"D:\\anaconda1\\lib\\site-packages\\joblib\\parallel.py\", line 861, in dispatch_one_batch\n",
      "    with self.parallel._lock:\n",
      "  File \"D:\\anaconda1\\lib\\site-packages\\joblib\\parallel.py\", line 779, in _dispatch\n",
      "  File \"D:\\anaconda1\\lib\\site-packages\\joblib\\_parallel_backends.py\", line 531, in apply_async\n",
      "    \"\"\"Shutdown the process or thread pool\"\"\"\n",
      "  File \"D:\\anaconda1\\lib\\site-packages\\joblib\\externals\\loky\\reusable_executor.py\", line 177, in submit\n",
      "    mp.util.debug(\n",
      "  File \"D:\\anaconda1\\lib\\site-packages\\joblib\\externals\\loky\\process_executor.py\", line 1115, in submit\n",
      "    # of the main loop of executor_manager_thread from another thread (e.g.\n",
      "joblib.externals.loky.process_executor.TerminatedWorkerError: A worker process managed by the executor was unexpectedly terminated. This could be caused by a segmentation fault while calling the function or by an excessive memory usage causing the Operating System to kill the worker.\n",
      "\n",
      "exception calling callback for <Future at 0x2570bc41e20 state=finished raised TerminatedWorkerError>\n",
      "Traceback (most recent call last):\n",
      "  File \"D:\\anaconda1\\lib\\site-packages\\joblib\\externals\\loky\\_base.py\", line 625, in _invoke_callbacks\n",
      "  File \"D:\\anaconda1\\lib\\site-packages\\joblib\\parallel.py\", line 359, in __call__\n",
      "    **backend_params\n",
      "  File \"D:\\anaconda1\\lib\\site-packages\\joblib\\parallel.py\", line 794, in dispatch_next\n",
      "    # registers the task outcome (TASK_ERROR or TASK_DONE), and schedules\n",
      "  File \"D:\\anaconda1\\lib\\site-packages\\joblib\\parallel.py\", line 861, in dispatch_one_batch\n",
      "    with self.parallel._lock:\n",
      "  File \"D:\\anaconda1\\lib\\site-packages\\joblib\\parallel.py\", line 779, in _dispatch\n",
      "  File \"D:\\anaconda1\\lib\\site-packages\\joblib\\_parallel_backends.py\", line 531, in apply_async\n",
      "    \"\"\"Shutdown the process or thread pool\"\"\"\n",
      "  File \"D:\\anaconda1\\lib\\site-packages\\joblib\\externals\\loky\\reusable_executor.py\", line 177, in submit\n",
      "    mp.util.debug(\n",
      "  File \"D:\\anaconda1\\lib\\site-packages\\joblib\\externals\\loky\\process_executor.py\", line 1115, in submit\n",
      "    # of the main loop of executor_manager_thread from another thread (e.g.\n",
      "joblib.externals.loky.process_executor.TerminatedWorkerError: A worker process managed by the executor was unexpectedly terminated. This could be caused by a segmentation fault while calling the function or by an excessive memory usage causing the Operating System to kill the worker.\n",
      "\n"
     ]
    },
    {
     "name": "stderr",
     "output_type": "stream",
     "text": [
      "exception calling callback for <Future at 0x2570358acd0 state=finished raised TerminatedWorkerError>\n",
      "Traceback (most recent call last):\n",
      "  File \"D:\\anaconda1\\lib\\site-packages\\joblib\\externals\\loky\\_base.py\", line 625, in _invoke_callbacks\n",
      "  File \"D:\\anaconda1\\lib\\site-packages\\joblib\\parallel.py\", line 359, in __call__\n",
      "    **backend_params\n",
      "  File \"D:\\anaconda1\\lib\\site-packages\\joblib\\parallel.py\", line 794, in dispatch_next\n",
      "    # registers the task outcome (TASK_ERROR or TASK_DONE), and schedules\n",
      "  File \"D:\\anaconda1\\lib\\site-packages\\joblib\\parallel.py\", line 861, in dispatch_one_batch\n",
      "    with self.parallel._lock:\n",
      "  File \"D:\\anaconda1\\lib\\site-packages\\joblib\\parallel.py\", line 779, in _dispatch\n",
      "  File \"D:\\anaconda1\\lib\\site-packages\\joblib\\_parallel_backends.py\", line 531, in apply_async\n",
      "    \"\"\"Shutdown the process or thread pool\"\"\"\n",
      "  File \"D:\\anaconda1\\lib\\site-packages\\joblib\\externals\\loky\\reusable_executor.py\", line 177, in submit\n",
      "    mp.util.debug(\n",
      "  File \"D:\\anaconda1\\lib\\site-packages\\joblib\\externals\\loky\\process_executor.py\", line 1115, in submit\n",
      "    # of the main loop of executor_manager_thread from another thread (e.g.\n",
      "joblib.externals.loky.process_executor.TerminatedWorkerError: A worker process managed by the executor was unexpectedly terminated. This could be caused by a segmentation fault while calling the function or by an excessive memory usage causing the Operating System to kill the worker.\n",
      "\n",
      "exception calling callback for <Future at 0x25704611fa0 state=finished raised TerminatedWorkerError>\n",
      "Traceback (most recent call last):\n",
      "  File \"D:\\anaconda1\\lib\\site-packages\\joblib\\externals\\loky\\_base.py\", line 625, in _invoke_callbacks\n",
      "  File \"D:\\anaconda1\\lib\\site-packages\\joblib\\parallel.py\", line 359, in __call__\n",
      "    **backend_params\n",
      "  File \"D:\\anaconda1\\lib\\site-packages\\joblib\\parallel.py\", line 794, in dispatch_next\n",
      "    # registers the task outcome (TASK_ERROR or TASK_DONE), and schedules\n",
      "  File \"D:\\anaconda1\\lib\\site-packages\\joblib\\parallel.py\", line 861, in dispatch_one_batch\n",
      "    with self.parallel._lock:\n",
      "  File \"D:\\anaconda1\\lib\\site-packages\\joblib\\parallel.py\", line 779, in _dispatch\n",
      "  File \"D:\\anaconda1\\lib\\site-packages\\joblib\\_parallel_backends.py\", line 531, in apply_async\n",
      "    \"\"\"Shutdown the process or thread pool\"\"\"\n",
      "  File \"D:\\anaconda1\\lib\\site-packages\\joblib\\externals\\loky\\reusable_executor.py\", line 177, in submit\n",
      "    mp.util.debug(\n",
      "  File \"D:\\anaconda1\\lib\\site-packages\\joblib\\externals\\loky\\process_executor.py\", line 1115, in submit\n",
      "    # of the main loop of executor_manager_thread from another thread (e.g.\n",
      "joblib.externals.loky.process_executor.TerminatedWorkerError: A worker process managed by the executor was unexpectedly terminated. This could be caused by a segmentation fault while calling the function or by an excessive memory usage causing the Operating System to kill the worker.\n",
      "\n",
      "exception calling callback for <Future at 0x2570bc74e20 state=finished raised TerminatedWorkerError>\n",
      "Traceback (most recent call last):\n",
      "  File \"D:\\anaconda1\\lib\\site-packages\\joblib\\externals\\loky\\_base.py\", line 625, in _invoke_callbacks\n",
      "  File \"D:\\anaconda1\\lib\\site-packages\\joblib\\parallel.py\", line 359, in __call__\n",
      "    **backend_params\n",
      "  File \"D:\\anaconda1\\lib\\site-packages\\joblib\\parallel.py\", line 794, in dispatch_next\n",
      "    # registers the task outcome (TASK_ERROR or TASK_DONE), and schedules\n",
      "  File \"D:\\anaconda1\\lib\\site-packages\\joblib\\parallel.py\", line 861, in dispatch_one_batch\n",
      "    with self.parallel._lock:\n",
      "  File \"D:\\anaconda1\\lib\\site-packages\\joblib\\parallel.py\", line 779, in _dispatch\n",
      "  File \"D:\\anaconda1\\lib\\site-packages\\joblib\\_parallel_backends.py\", line 531, in apply_async\n",
      "    \"\"\"Shutdown the process or thread pool\"\"\"\n",
      "  File \"D:\\anaconda1\\lib\\site-packages\\joblib\\externals\\loky\\reusable_executor.py\", line 177, in submit\n",
      "    mp.util.debug(\n",
      "  File \"D:\\anaconda1\\lib\\site-packages\\joblib\\externals\\loky\\process_executor.py\", line 1115, in submit\n",
      "    # of the main loop of executor_manager_thread from another thread (e.g.\n",
      "joblib.externals.loky.process_executor.TerminatedWorkerError: A worker process managed by the executor was unexpectedly terminated. This could be caused by a segmentation fault while calling the function or by an excessive memory usage causing the Operating System to kill the worker.\n",
      "\n",
      "D:\\anaconda1\\lib\\site-packages\\sklearn\\model_selection\\_validation.py:372: FitFailedWarning: \n",
      "5 fits failed out of a total of 5.\n",
      "The score on these train-test partitions for these parameters will be set to nan.\n",
      "If these failures are not expected, you can try to debug them by setting error_score='raise'.\n",
      "\n",
      "Below are more details about the failures:\n",
      "--------------------------------------------------------------------------------\n",
      "1 fits failed with the following error:\n",
      "Traceback (most recent call last):\n",
      "  File \"D:\\anaconda1\\lib\\site-packages\\sklearn\\model_selection\\_validation.py\", line 680, in _fit_and_score\n",
      "    estimator.fit(X_train, y_train, **fit_params)\n",
      "  File \"D:\\anaconda1\\lib\\site-packages\\sklearn\\ensemble\\_forest.py\", line 450, in fit\n",
      "    trees = Parallel(\n",
      "  File \"D:\\anaconda1\\lib\\site-packages\\joblib\\parallel.py\", line 1056, in __call__\n",
      "  File \"D:\\anaconda1\\lib\\site-packages\\joblib\\parallel.py\", line 935, in retrieve\n",
      "    Read more in the :ref:`User Guide <parallel>`.\n",
      "  File \"D:\\anaconda1\\lib\\site-packages\\joblib\\_parallel_backends.py\", line 542, in wrap_future_result\n",
      "    def configure(self, n_jobs=1, parallel=None, prefer=None, require=None,\n",
      "  File \"D:\\anaconda1\\lib\\concurrent\\futures\\_base.py\", line 446, in result\n",
      "    return self.__get_result()\n",
      "  File \"D:\\anaconda1\\lib\\concurrent\\futures\\_base.py\", line 391, in __get_result\n",
      "    raise self._exception\n",
      "  File \"D:\\anaconda1\\lib\\site-packages\\joblib\\externals\\loky\\_base.py\", line 625, in _invoke_callbacks\n",
      "  File \"D:\\anaconda1\\lib\\site-packages\\joblib\\parallel.py\", line 359, in __call__\n",
      "    **backend_params\n",
      "  File \"D:\\anaconda1\\lib\\site-packages\\joblib\\parallel.py\", line 794, in dispatch_next\n",
      "    # registers the task outcome (TASK_ERROR or TASK_DONE), and schedules\n",
      "  File \"D:\\anaconda1\\lib\\site-packages\\joblib\\parallel.py\", line 861, in dispatch_one_batch\n",
      "    with self.parallel._lock:\n",
      "  File \"D:\\anaconda1\\lib\\site-packages\\joblib\\parallel.py\", line 779, in _dispatch\n",
      "  File \"D:\\anaconda1\\lib\\site-packages\\joblib\\_parallel_backends.py\", line 531, in apply_async\n",
      "    \"\"\"Shutdown the process or thread pool\"\"\"\n",
      "  File \"D:\\anaconda1\\lib\\site-packages\\joblib\\externals\\loky\\reusable_executor.py\", line 177, in submit\n",
      "    mp.util.debug(\n",
      "  File \"D:\\anaconda1\\lib\\site-packages\\joblib\\externals\\loky\\process_executor.py\", line 1115, in submit\n",
      "    # of the main loop of executor_manager_thread from another thread (e.g.\n",
      "  File \"D:\\anaconda1\\lib\\site-packages\\joblib\\externals\\loky\\_base.py\", line 625, in _invoke_callbacks\n",
      "  File \"D:\\anaconda1\\lib\\site-packages\\joblib\\parallel.py\", line 359, in __call__\n",
      "    **backend_params\n",
      "  File \"D:\\anaconda1\\lib\\site-packages\\joblib\\parallel.py\", line 794, in dispatch_next\n",
      "    # registers the task outcome (TASK_ERROR or TASK_DONE), and schedules\n",
      "  File \"D:\\anaconda1\\lib\\site-packages\\joblib\\parallel.py\", line 861, in dispatch_one_batch\n",
      "    with self.parallel._lock:\n",
      "  File \"D:\\anaconda1\\lib\\site-packages\\joblib\\parallel.py\", line 779, in _dispatch\n",
      "  File \"D:\\anaconda1\\lib\\site-packages\\joblib\\_parallel_backends.py\", line 531, in apply_async\n",
      "    \"\"\"Shutdown the process or thread pool\"\"\"\n",
      "  File \"D:\\anaconda1\\lib\\site-packages\\joblib\\externals\\loky\\reusable_executor.py\", line 177, in submit\n",
      "    mp.util.debug(\n",
      "  File \"D:\\anaconda1\\lib\\site-packages\\joblib\\externals\\loky\\process_executor.py\", line 1115, in submit\n",
      "    # of the main loop of executor_manager_thread from another thread (e.g.\n",
      "  File \"D:\\anaconda1\\lib\\site-packages\\joblib\\externals\\loky\\_base.py\", line 625, in _invoke_callbacks\n",
      "  File \"D:\\anaconda1\\lib\\site-packages\\joblib\\parallel.py\", line 359, in __call__\n",
      "    **backend_params\n",
      "  File \"D:\\anaconda1\\lib\\site-packages\\joblib\\parallel.py\", line 794, in dispatch_next\n",
      "    # registers the task outcome (TASK_ERROR or TASK_DONE), and schedules\n",
      "  File \"D:\\anaconda1\\lib\\site-packages\\joblib\\parallel.py\", line 861, in dispatch_one_batch\n",
      "    with self.parallel._lock:\n",
      "  File \"D:\\anaconda1\\lib\\site-packages\\joblib\\parallel.py\", line 779, in _dispatch\n",
      "  File \"D:\\anaconda1\\lib\\site-packages\\joblib\\_parallel_backends.py\", line 531, in apply_async\n",
      "    \"\"\"Shutdown the process or thread pool\"\"\"\n",
      "  File \"D:\\anaconda1\\lib\\site-packages\\joblib\\externals\\loky\\reusable_executor.py\", line 177, in submit\n",
      "    mp.util.debug(\n",
      "  File \"D:\\anaconda1\\lib\\site-packages\\joblib\\externals\\loky\\process_executor.py\", line 1115, in submit\n",
      "    # of the main loop of executor_manager_thread from another thread (e.g.\n",
      "joblib.externals.loky.process_executor.TerminatedWorkerError: A worker process managed by the executor was unexpectedly terminated. This could be caused by a segmentation fault while calling the function or by an excessive memory usage causing the Operating System to kill the worker.\n",
      "\n",
      "\n",
      "--------------------------------------------------------------------------------\n",
      "4 fits failed with the following error:\n",
      "Traceback (most recent call last):\n",
      "  File \"D:\\anaconda1\\lib\\site-packages\\sklearn\\model_selection\\_validation.py\", line 680, in _fit_and_score\n",
      "    estimator.fit(X_train, y_train, **fit_params)\n",
      "  File \"D:\\anaconda1\\lib\\site-packages\\sklearn\\ensemble\\_forest.py\", line 450, in fit\n",
      "    trees = Parallel(\n",
      "  File \"D:\\anaconda1\\lib\\site-packages\\joblib\\parallel.py\", line 1056, in __call__\n",
      "  File \"D:\\anaconda1\\lib\\site-packages\\joblib\\parallel.py\", line 935, in retrieve\n",
      "    Read more in the :ref:`User Guide <parallel>`.\n",
      "  File \"D:\\anaconda1\\lib\\site-packages\\joblib\\_parallel_backends.py\", line 542, in wrap_future_result\n",
      "    def configure(self, n_jobs=1, parallel=None, prefer=None, require=None,\n",
      "  File \"D:\\anaconda1\\lib\\concurrent\\futures\\_base.py\", line 446, in result\n",
      "    return self.__get_result()\n",
      "  File \"D:\\anaconda1\\lib\\concurrent\\futures\\_base.py\", line 391, in __get_result\n",
      "    raise self._exception\n",
      "  File \"D:\\anaconda1\\lib\\site-packages\\joblib\\externals\\loky\\_base.py\", line 625, in _invoke_callbacks\n",
      "  File \"D:\\anaconda1\\lib\\site-packages\\joblib\\parallel.py\", line 359, in __call__\n",
      "    **backend_params\n",
      "  File \"D:\\anaconda1\\lib\\site-packages\\joblib\\parallel.py\", line 794, in dispatch_next\n",
      "    # registers the task outcome (TASK_ERROR or TASK_DONE), and schedules\n",
      "  File \"D:\\anaconda1\\lib\\site-packages\\joblib\\parallel.py\", line 861, in dispatch_one_batch\n",
      "    with self.parallel._lock:\n",
      "  File \"D:\\anaconda1\\lib\\site-packages\\joblib\\parallel.py\", line 779, in _dispatch\n",
      "  File \"D:\\anaconda1\\lib\\site-packages\\joblib\\_parallel_backends.py\", line 531, in apply_async\n",
      "    \"\"\"Shutdown the process or thread pool\"\"\"\n",
      "  File \"D:\\anaconda1\\lib\\site-packages\\joblib\\externals\\loky\\reusable_executor.py\", line 177, in submit\n",
      "    mp.util.debug(\n",
      "  File \"D:\\anaconda1\\lib\\site-packages\\joblib\\externals\\loky\\process_executor.py\", line 1115, in submit\n",
      "    # of the main loop of executor_manager_thread from another thread (e.g.\n",
      "joblib.externals.loky.process_executor.TerminatedWorkerError: A worker process managed by the executor was unexpectedly terminated. This could be caused by a segmentation fault while calling the function or by an excessive memory usage causing the Operating System to kill the worker.\n",
      "\n",
      "\n"
     ]
    },
    {
     "name": "stdout",
     "output_type": "stream",
     "text": [
      "Cross-validation scores for Okhaldhunga: [nan nan nan nan nan]\n",
      "Mean cross-validation accuracy for Okhaldhunga: nan\n",
      "Accuracy of Okhaldhunga: 0.32\n"
     ]
    },
    {
     "name": "stderr",
     "output_type": "stream",
     "text": [
      "exception calling callback for <Future at 0x257035c1940 state=finished raised TerminatedWorkerError>\n",
      "Traceback (most recent call last):\n",
      "  File \"D:\\anaconda1\\lib\\site-packages\\joblib\\externals\\loky\\_base.py\", line 625, in _invoke_callbacks\n",
      "  File \"D:\\anaconda1\\lib\\site-packages\\joblib\\parallel.py\", line 359, in __call__\n",
      "    **backend_params\n",
      "  File \"D:\\anaconda1\\lib\\site-packages\\joblib\\parallel.py\", line 794, in dispatch_next\n",
      "    # registers the task outcome (TASK_ERROR or TASK_DONE), and schedules\n",
      "  File \"D:\\anaconda1\\lib\\site-packages\\joblib\\parallel.py\", line 861, in dispatch_one_batch\n",
      "    with self.parallel._lock:\n",
      "  File \"D:\\anaconda1\\lib\\site-packages\\joblib\\parallel.py\", line 779, in _dispatch\n",
      "  File \"D:\\anaconda1\\lib\\site-packages\\joblib\\_parallel_backends.py\", line 531, in apply_async\n",
      "    \"\"\"Shutdown the process or thread pool\"\"\"\n",
      "  File \"D:\\anaconda1\\lib\\site-packages\\joblib\\externals\\loky\\reusable_executor.py\", line 177, in submit\n",
      "    mp.util.debug(\n",
      "  File \"D:\\anaconda1\\lib\\site-packages\\joblib\\externals\\loky\\process_executor.py\", line 1115, in submit\n",
      "    # of the main loop of executor_manager_thread from another thread (e.g.\n",
      "joblib.externals.loky.process_executor.TerminatedWorkerError: A worker process managed by the executor was unexpectedly terminated. This could be caused by a segmentation fault while calling the function or by an excessive memory usage causing the Operating System to kill the worker.\n",
      "\n",
      "exception calling callback for <Future at 0x257037b03d0 state=finished raised TerminatedWorkerError>\n",
      "Traceback (most recent call last):\n",
      "  File \"D:\\anaconda1\\lib\\site-packages\\joblib\\externals\\loky\\_base.py\", line 625, in _invoke_callbacks\n",
      "  File \"D:\\anaconda1\\lib\\site-packages\\joblib\\parallel.py\", line 359, in __call__\n",
      "    **backend_params\n",
      "  File \"D:\\anaconda1\\lib\\site-packages\\joblib\\parallel.py\", line 794, in dispatch_next\n",
      "    # registers the task outcome (TASK_ERROR or TASK_DONE), and schedules\n",
      "  File \"D:\\anaconda1\\lib\\site-packages\\joblib\\parallel.py\", line 861, in dispatch_one_batch\n",
      "    with self.parallel._lock:\n",
      "  File \"D:\\anaconda1\\lib\\site-packages\\joblib\\parallel.py\", line 779, in _dispatch\n",
      "  File \"D:\\anaconda1\\lib\\site-packages\\joblib\\_parallel_backends.py\", line 531, in apply_async\n",
      "    \"\"\"Shutdown the process or thread pool\"\"\"\n",
      "  File \"D:\\anaconda1\\lib\\site-packages\\joblib\\externals\\loky\\reusable_executor.py\", line 177, in submit\n",
      "    mp.util.debug(\n",
      "  File \"D:\\anaconda1\\lib\\site-packages\\joblib\\externals\\loky\\process_executor.py\", line 1115, in submit\n",
      "    # of the main loop of executor_manager_thread from another thread (e.g.\n",
      "joblib.externals.loky.process_executor.TerminatedWorkerError: A worker process managed by the executor was unexpectedly terminated. This could be caused by a segmentation fault while calling the function or by an excessive memory usage causing the Operating System to kill the worker.\n",
      "\n",
      "exception calling callback for <Future at 0x257037c9580 state=finished raised TerminatedWorkerError>\n",
      "Traceback (most recent call last):\n",
      "  File \"D:\\anaconda1\\lib\\site-packages\\joblib\\externals\\loky\\_base.py\", line 625, in _invoke_callbacks\n",
      "  File \"D:\\anaconda1\\lib\\site-packages\\joblib\\parallel.py\", line 359, in __call__\n",
      "    **backend_params\n",
      "  File \"D:\\anaconda1\\lib\\site-packages\\joblib\\parallel.py\", line 794, in dispatch_next\n",
      "    # registers the task outcome (TASK_ERROR or TASK_DONE), and schedules\n",
      "  File \"D:\\anaconda1\\lib\\site-packages\\joblib\\parallel.py\", line 861, in dispatch_one_batch\n",
      "    with self.parallel._lock:\n",
      "  File \"D:\\anaconda1\\lib\\site-packages\\joblib\\parallel.py\", line 779, in _dispatch\n",
      "  File \"D:\\anaconda1\\lib\\site-packages\\joblib\\_parallel_backends.py\", line 531, in apply_async\n",
      "    \"\"\"Shutdown the process or thread pool\"\"\"\n",
      "  File \"D:\\anaconda1\\lib\\site-packages\\joblib\\externals\\loky\\reusable_executor.py\", line 177, in submit\n",
      "    mp.util.debug(\n",
      "  File \"D:\\anaconda1\\lib\\site-packages\\joblib\\externals\\loky\\process_executor.py\", line 1115, in submit\n",
      "    # of the main loop of executor_manager_thread from another thread (e.g.\n",
      "joblib.externals.loky.process_executor.TerminatedWorkerError: A worker process managed by the executor was unexpectedly terminated. This could be caused by a segmentation fault while calling the function or by an excessive memory usage causing the Operating System to kill the worker.\n",
      "\n",
      "exception calling callback for <Future at 0x2570bc71f10 state=finished raised TerminatedWorkerError>\n",
      "Traceback (most recent call last):\n",
      "  File \"D:\\anaconda1\\lib\\site-packages\\joblib\\externals\\loky\\_base.py\", line 625, in _invoke_callbacks\n",
      "  File \"D:\\anaconda1\\lib\\site-packages\\joblib\\parallel.py\", line 359, in __call__\n",
      "    **backend_params\n",
      "  File \"D:\\anaconda1\\lib\\site-packages\\joblib\\parallel.py\", line 794, in dispatch_next\n",
      "    # registers the task outcome (TASK_ERROR or TASK_DONE), and schedules\n",
      "  File \"D:\\anaconda1\\lib\\site-packages\\joblib\\parallel.py\", line 861, in dispatch_one_batch\n",
      "    with self.parallel._lock:\n",
      "  File \"D:\\anaconda1\\lib\\site-packages\\joblib\\parallel.py\", line 779, in _dispatch\n",
      "  File \"D:\\anaconda1\\lib\\site-packages\\joblib\\_parallel_backends.py\", line 531, in apply_async\n",
      "    \"\"\"Shutdown the process or thread pool\"\"\"\n",
      "  File \"D:\\anaconda1\\lib\\site-packages\\joblib\\externals\\loky\\reusable_executor.py\", line 177, in submit\n",
      "    mp.util.debug(\n",
      "  File \"D:\\anaconda1\\lib\\site-packages\\joblib\\externals\\loky\\process_executor.py\", line 1115, in submit\n",
      "    # of the main loop of executor_manager_thread from another thread (e.g.\n",
      "joblib.externals.loky.process_executor.TerminatedWorkerError: A worker process managed by the executor was unexpectedly terminated. This could be caused by a segmentation fault while calling the function or by an excessive memory usage causing the Operating System to kill the worker.\n",
      "\n",
      "exception calling callback for <Future at 0x257037d01f0 state=finished raised TerminatedWorkerError>\n",
      "Traceback (most recent call last):\n",
      "  File \"D:\\anaconda1\\lib\\site-packages\\joblib\\externals\\loky\\_base.py\", line 625, in _invoke_callbacks\n",
      "  File \"D:\\anaconda1\\lib\\site-packages\\joblib\\parallel.py\", line 359, in __call__\n",
      "    **backend_params\n",
      "  File \"D:\\anaconda1\\lib\\site-packages\\joblib\\parallel.py\", line 794, in dispatch_next\n",
      "    # registers the task outcome (TASK_ERROR or TASK_DONE), and schedules\n",
      "  File \"D:\\anaconda1\\lib\\site-packages\\joblib\\parallel.py\", line 861, in dispatch_one_batch\n",
      "    with self.parallel._lock:\n",
      "  File \"D:\\anaconda1\\lib\\site-packages\\joblib\\parallel.py\", line 779, in _dispatch\n",
      "  File \"D:\\anaconda1\\lib\\site-packages\\joblib\\_parallel_backends.py\", line 531, in apply_async\n",
      "    \"\"\"Shutdown the process or thread pool\"\"\"\n",
      "  File \"D:\\anaconda1\\lib\\site-packages\\joblib\\externals\\loky\\reusable_executor.py\", line 177, in submit\n",
      "    mp.util.debug(\n",
      "  File \"D:\\anaconda1\\lib\\site-packages\\joblib\\externals\\loky\\process_executor.py\", line 1115, in submit\n",
      "    # of the main loop of executor_manager_thread from another thread (e.g.\n",
      "joblib.externals.loky.process_executor.TerminatedWorkerError: A worker process managed by the executor was unexpectedly terminated. This could be caused by a segmentation fault while calling the function or by an excessive memory usage causing the Operating System to kill the worker.\n",
      "\n",
      "D:\\anaconda1\\lib\\site-packages\\sklearn\\model_selection\\_validation.py:372: FitFailedWarning: \n",
      "5 fits failed out of a total of 5.\n",
      "The score on these train-test partitions for these parameters will be set to nan.\n",
      "If these failures are not expected, you can try to debug them by setting error_score='raise'.\n",
      "\n",
      "Below are more details about the failures:\n",
      "--------------------------------------------------------------------------------\n",
      "5 fits failed with the following error:\n",
      "Traceback (most recent call last):\n",
      "  File \"D:\\anaconda1\\lib\\site-packages\\sklearn\\model_selection\\_validation.py\", line 680, in _fit_and_score\n",
      "    estimator.fit(X_train, y_train, **fit_params)\n",
      "  File \"D:\\anaconda1\\lib\\site-packages\\sklearn\\ensemble\\_forest.py\", line 450, in fit\n",
      "    trees = Parallel(\n",
      "  File \"D:\\anaconda1\\lib\\site-packages\\joblib\\parallel.py\", line 1056, in __call__\n",
      "  File \"D:\\anaconda1\\lib\\site-packages\\joblib\\parallel.py\", line 935, in retrieve\n",
      "    Read more in the :ref:`User Guide <parallel>`.\n",
      "  File \"D:\\anaconda1\\lib\\site-packages\\joblib\\_parallel_backends.py\", line 542, in wrap_future_result\n",
      "    def configure(self, n_jobs=1, parallel=None, prefer=None, require=None,\n",
      "  File \"D:\\anaconda1\\lib\\concurrent\\futures\\_base.py\", line 446, in result\n",
      "    return self.__get_result()\n",
      "  File \"D:\\anaconda1\\lib\\concurrent\\futures\\_base.py\", line 391, in __get_result\n",
      "    raise self._exception\n",
      "  File \"D:\\anaconda1\\lib\\site-packages\\joblib\\externals\\loky\\_base.py\", line 625, in _invoke_callbacks\n",
      "  File \"D:\\anaconda1\\lib\\site-packages\\joblib\\parallel.py\", line 359, in __call__\n",
      "    **backend_params\n",
      "  File \"D:\\anaconda1\\lib\\site-packages\\joblib\\parallel.py\", line 794, in dispatch_next\n",
      "    # registers the task outcome (TASK_ERROR or TASK_DONE), and schedules\n",
      "  File \"D:\\anaconda1\\lib\\site-packages\\joblib\\parallel.py\", line 861, in dispatch_one_batch\n",
      "    with self.parallel._lock:\n",
      "  File \"D:\\anaconda1\\lib\\site-packages\\joblib\\parallel.py\", line 779, in _dispatch\n",
      "  File \"D:\\anaconda1\\lib\\site-packages\\joblib\\_parallel_backends.py\", line 531, in apply_async\n",
      "    \"\"\"Shutdown the process or thread pool\"\"\"\n",
      "  File \"D:\\anaconda1\\lib\\site-packages\\joblib\\externals\\loky\\reusable_executor.py\", line 177, in submit\n",
      "    mp.util.debug(\n",
      "  File \"D:\\anaconda1\\lib\\site-packages\\joblib\\externals\\loky\\process_executor.py\", line 1115, in submit\n",
      "    # of the main loop of executor_manager_thread from another thread (e.g.\n",
      "joblib.externals.loky.process_executor.TerminatedWorkerError: A worker process managed by the executor was unexpectedly terminated. This could be caused by a segmentation fault while calling the function or by an excessive memory usage causing the Operating System to kill the worker.\n",
      "\n",
      "\n"
     ]
    },
    {
     "name": "stdout",
     "output_type": "stream",
     "text": [
      "Cross-validation scores for Ramechhap: [nan nan nan nan nan]\n",
      "Mean cross-validation accuracy for Ramechhap: nan\n",
      "Accuracy of Ramechhap: 0.36\n"
     ]
    },
    {
     "name": "stderr",
     "output_type": "stream",
     "text": [
      "exception calling callback for <Future at 0x257035d9b80 state=finished raised TerminatedWorkerError>\n",
      "Traceback (most recent call last):\n",
      "  File \"D:\\anaconda1\\lib\\site-packages\\joblib\\externals\\loky\\_base.py\", line 625, in _invoke_callbacks\n",
      "  File \"D:\\anaconda1\\lib\\site-packages\\joblib\\parallel.py\", line 359, in __call__\n",
      "    **backend_params\n",
      "  File \"D:\\anaconda1\\lib\\site-packages\\joblib\\parallel.py\", line 794, in dispatch_next\n",
      "    # registers the task outcome (TASK_ERROR or TASK_DONE), and schedules\n",
      "  File \"D:\\anaconda1\\lib\\site-packages\\joblib\\parallel.py\", line 861, in dispatch_one_batch\n",
      "    with self.parallel._lock:\n",
      "  File \"D:\\anaconda1\\lib\\site-packages\\joblib\\parallel.py\", line 779, in _dispatch\n",
      "  File \"D:\\anaconda1\\lib\\site-packages\\joblib\\_parallel_backends.py\", line 531, in apply_async\n",
      "    \"\"\"Shutdown the process or thread pool\"\"\"\n",
      "  File \"D:\\anaconda1\\lib\\site-packages\\joblib\\externals\\loky\\reusable_executor.py\", line 177, in submit\n",
      "    mp.util.debug(\n",
      "  File \"D:\\anaconda1\\lib\\site-packages\\joblib\\externals\\loky\\process_executor.py\", line 1115, in submit\n",
      "    # of the main loop of executor_manager_thread from another thread (e.g.\n",
      "joblib.externals.loky.process_executor.TerminatedWorkerError: A worker process managed by the executor was unexpectedly terminated. This could be caused by a segmentation fault while calling the function or by an excessive memory usage causing the Operating System to kill the worker.\n",
      "\n",
      "exception calling callback for <Future at 0x257035fa490 state=finished raised TerminatedWorkerError>\n",
      "Traceback (most recent call last):\n",
      "  File \"D:\\anaconda1\\lib\\site-packages\\joblib\\externals\\loky\\_base.py\", line 625, in _invoke_callbacks\n",
      "  File \"D:\\anaconda1\\lib\\site-packages\\joblib\\parallel.py\", line 359, in __call__\n",
      "    **backend_params\n",
      "  File \"D:\\anaconda1\\lib\\site-packages\\joblib\\parallel.py\", line 794, in dispatch_next\n",
      "    # registers the task outcome (TASK_ERROR or TASK_DONE), and schedules\n",
      "  File \"D:\\anaconda1\\lib\\site-packages\\joblib\\parallel.py\", line 861, in dispatch_one_batch\n",
      "    with self.parallel._lock:\n",
      "  File \"D:\\anaconda1\\lib\\site-packages\\joblib\\parallel.py\", line 779, in _dispatch\n",
      "  File \"D:\\anaconda1\\lib\\site-packages\\joblib\\_parallel_backends.py\", line 531, in apply_async\n",
      "    \"\"\"Shutdown the process or thread pool\"\"\"\n",
      "  File \"D:\\anaconda1\\lib\\site-packages\\joblib\\externals\\loky\\reusable_executor.py\", line 177, in submit\n",
      "    mp.util.debug(\n",
      "  File \"D:\\anaconda1\\lib\\site-packages\\joblib\\externals\\loky\\process_executor.py\", line 1115, in submit\n",
      "    # of the main loop of executor_manager_thread from another thread (e.g.\n",
      "joblib.externals.loky.process_executor.TerminatedWorkerError: A worker process managed by the executor was unexpectedly terminated. This could be caused by a segmentation fault while calling the function or by an excessive memory usage causing the Operating System to kill the worker.\n",
      "\n",
      "exception calling callback for <Future at 0x257036178e0 state=finished raised TerminatedWorkerError>\n",
      "Traceback (most recent call last):\n",
      "  File \"D:\\anaconda1\\lib\\site-packages\\joblib\\externals\\loky\\_base.py\", line 625, in _invoke_callbacks\n",
      "  File \"D:\\anaconda1\\lib\\site-packages\\joblib\\parallel.py\", line 359, in __call__\n",
      "    **backend_params\n",
      "  File \"D:\\anaconda1\\lib\\site-packages\\joblib\\parallel.py\", line 794, in dispatch_next\n",
      "    # registers the task outcome (TASK_ERROR or TASK_DONE), and schedules\n",
      "  File \"D:\\anaconda1\\lib\\site-packages\\joblib\\parallel.py\", line 861, in dispatch_one_batch\n",
      "    with self.parallel._lock:\n",
      "  File \"D:\\anaconda1\\lib\\site-packages\\joblib\\parallel.py\", line 779, in _dispatch\n",
      "  File \"D:\\anaconda1\\lib\\site-packages\\joblib\\_parallel_backends.py\", line 531, in apply_async\n",
      "    \"\"\"Shutdown the process or thread pool\"\"\"\n",
      "  File \"D:\\anaconda1\\lib\\site-packages\\joblib\\externals\\loky\\reusable_executor.py\", line 177, in submit\n",
      "    mp.util.debug(\n",
      "  File \"D:\\anaconda1\\lib\\site-packages\\joblib\\externals\\loky\\process_executor.py\", line 1115, in submit\n",
      "    # of the main loop of executor_manager_thread from another thread (e.g.\n",
      "joblib.externals.loky.process_executor.TerminatedWorkerError: A worker process managed by the executor was unexpectedly terminated. This could be caused by a segmentation fault while calling the function or by an excessive memory usage causing the Operating System to kill the worker.\n",
      "\n",
      "exception calling callback for <Future at 0x2570361c9d0 state=finished raised TerminatedWorkerError>\n",
      "Traceback (most recent call last):\n",
      "  File \"D:\\anaconda1\\lib\\site-packages\\joblib\\externals\\loky\\_base.py\", line 625, in _invoke_callbacks\n",
      "  File \"D:\\anaconda1\\lib\\site-packages\\joblib\\parallel.py\", line 359, in __call__\n",
      "    **backend_params\n",
      "  File \"D:\\anaconda1\\lib\\site-packages\\joblib\\parallel.py\", line 794, in dispatch_next\n",
      "    # registers the task outcome (TASK_ERROR or TASK_DONE), and schedules\n",
      "  File \"D:\\anaconda1\\lib\\site-packages\\joblib\\parallel.py\", line 861, in dispatch_one_batch\n",
      "    with self.parallel._lock:\n",
      "  File \"D:\\anaconda1\\lib\\site-packages\\joblib\\parallel.py\", line 779, in _dispatch\n",
      "  File \"D:\\anaconda1\\lib\\site-packages\\joblib\\_parallel_backends.py\", line 531, in apply_async\n",
      "    \"\"\"Shutdown the process or thread pool\"\"\"\n",
      "  File \"D:\\anaconda1\\lib\\site-packages\\joblib\\externals\\loky\\reusable_executor.py\", line 177, in submit\n",
      "    mp.util.debug(\n",
      "  File \"D:\\anaconda1\\lib\\site-packages\\joblib\\externals\\loky\\process_executor.py\", line 1115, in submit\n",
      "    # of the main loop of executor_manager_thread from another thread (e.g.\n",
      "joblib.externals.loky.process_executor.TerminatedWorkerError: A worker process managed by the executor was unexpectedly terminated. This could be caused by a segmentation fault while calling the function or by an excessive memory usage causing the Operating System to kill the worker.\n",
      "\n",
      "exception calling callback for <Future at 0x257037d0c40 state=finished raised TerminatedWorkerError>\n",
      "Traceback (most recent call last):\n",
      "  File \"D:\\anaconda1\\lib\\site-packages\\joblib\\externals\\loky\\_base.py\", line 625, in _invoke_callbacks\n",
      "  File \"D:\\anaconda1\\lib\\site-packages\\joblib\\parallel.py\", line 359, in __call__\n",
      "    **backend_params\n",
      "  File \"D:\\anaconda1\\lib\\site-packages\\joblib\\parallel.py\", line 794, in dispatch_next\n",
      "    # registers the task outcome (TASK_ERROR or TASK_DONE), and schedules\n",
      "  File \"D:\\anaconda1\\lib\\site-packages\\joblib\\parallel.py\", line 861, in dispatch_one_batch\n",
      "    with self.parallel._lock:\n",
      "  File \"D:\\anaconda1\\lib\\site-packages\\joblib\\parallel.py\", line 779, in _dispatch\n",
      "  File \"D:\\anaconda1\\lib\\site-packages\\joblib\\_parallel_backends.py\", line 531, in apply_async\n",
      "    \"\"\"Shutdown the process or thread pool\"\"\"\n",
      "  File \"D:\\anaconda1\\lib\\site-packages\\joblib\\externals\\loky\\reusable_executor.py\", line 177, in submit\n",
      "    mp.util.debug(\n",
      "  File \"D:\\anaconda1\\lib\\site-packages\\joblib\\externals\\loky\\process_executor.py\", line 1115, in submit\n",
      "    # of the main loop of executor_manager_thread from another thread (e.g.\n",
      "joblib.externals.loky.process_executor.TerminatedWorkerError: A worker process managed by the executor was unexpectedly terminated. This could be caused by a segmentation fault while calling the function or by an excessive memory usage causing the Operating System to kill the worker.\n",
      "\n",
      "D:\\anaconda1\\lib\\site-packages\\sklearn\\model_selection\\_validation.py:372: FitFailedWarning: \n",
      "5 fits failed out of a total of 5.\n",
      "The score on these train-test partitions for these parameters will be set to nan.\n",
      "If these failures are not expected, you can try to debug them by setting error_score='raise'.\n",
      "\n",
      "Below are more details about the failures:\n",
      "--------------------------------------------------------------------------------\n",
      "5 fits failed with the following error:\n",
      "Traceback (most recent call last):\n",
      "  File \"D:\\anaconda1\\lib\\site-packages\\sklearn\\model_selection\\_validation.py\", line 680, in _fit_and_score\n",
      "    estimator.fit(X_train, y_train, **fit_params)\n",
      "  File \"D:\\anaconda1\\lib\\site-packages\\sklearn\\ensemble\\_forest.py\", line 450, in fit\n",
      "    trees = Parallel(\n",
      "  File \"D:\\anaconda1\\lib\\site-packages\\joblib\\parallel.py\", line 1056, in __call__\n",
      "  File \"D:\\anaconda1\\lib\\site-packages\\joblib\\parallel.py\", line 935, in retrieve\n",
      "    Read more in the :ref:`User Guide <parallel>`.\n",
      "  File \"D:\\anaconda1\\lib\\site-packages\\joblib\\_parallel_backends.py\", line 542, in wrap_future_result\n",
      "    def configure(self, n_jobs=1, parallel=None, prefer=None, require=None,\n",
      "  File \"D:\\anaconda1\\lib\\concurrent\\futures\\_base.py\", line 446, in result\n",
      "    return self.__get_result()\n",
      "  File \"D:\\anaconda1\\lib\\concurrent\\futures\\_base.py\", line 391, in __get_result\n",
      "    raise self._exception\n",
      "  File \"D:\\anaconda1\\lib\\site-packages\\joblib\\externals\\loky\\_base.py\", line 625, in _invoke_callbacks\n",
      "  File \"D:\\anaconda1\\lib\\site-packages\\joblib\\parallel.py\", line 359, in __call__\n",
      "    **backend_params\n",
      "  File \"D:\\anaconda1\\lib\\site-packages\\joblib\\parallel.py\", line 794, in dispatch_next\n",
      "    # registers the task outcome (TASK_ERROR or TASK_DONE), and schedules\n",
      "  File \"D:\\anaconda1\\lib\\site-packages\\joblib\\parallel.py\", line 861, in dispatch_one_batch\n",
      "    with self.parallel._lock:\n",
      "  File \"D:\\anaconda1\\lib\\site-packages\\joblib\\parallel.py\", line 779, in _dispatch\n",
      "  File \"D:\\anaconda1\\lib\\site-packages\\joblib\\_parallel_backends.py\", line 531, in apply_async\n",
      "    \"\"\"Shutdown the process or thread pool\"\"\"\n",
      "  File \"D:\\anaconda1\\lib\\site-packages\\joblib\\externals\\loky\\reusable_executor.py\", line 177, in submit\n",
      "    mp.util.debug(\n",
      "  File \"D:\\anaconda1\\lib\\site-packages\\joblib\\externals\\loky\\process_executor.py\", line 1115, in submit\n",
      "    # of the main loop of executor_manager_thread from another thread (e.g.\n",
      "joblib.externals.loky.process_executor.TerminatedWorkerError: A worker process managed by the executor was unexpectedly terminated. This could be caused by a segmentation fault while calling the function or by an excessive memory usage causing the Operating System to kill the worker.\n",
      "\n",
      "\n"
     ]
    },
    {
     "name": "stdout",
     "output_type": "stream",
     "text": [
      "Cross-validation scores for Rasuwa: [nan nan nan nan nan]\n",
      "Mean cross-validation accuracy for Rasuwa: nan\n",
      "Accuracy of Rasuwa: 0.52\n"
     ]
    }
   ],
   "source": [
    "from sklearn.model_selection import train_test_split\n",
    "from sklearn.preprocessing import StandardScaler\n",
    "from sklearn.ensemble import RandomForestClassifier\n",
    "from sklearn.metrics import accuracy_score\n",
    "from imblearn.over_sampling import RandomOverSampler\n",
    "from collections import Counter\n",
    "\n",
    "scaler = StandardScaler()\n",
    "\n",
    "for name, group in grouped_dataframes:\n",
    "    X = group.drop(['district_name', 'damage_grade'], axis=1)\n",
    "    y = group['damage_grade']\n",
    "    \n",
    "    # 使用RandomOverSampler进行过采样\n",
    "    oversampler = RandomOverSampler(random_state=42)\n",
    "    X_resampled, y_resampled = oversampler.fit_resample(X, y)\n",
    "    \n",
    "    X_train, X_test, y_train, y_test = train_test_split(X_resampled, y_resampled, test_size=0.2, random_state=42)\n",
    "    X_train_scaled = scaler.fit_transform(X_train)\n",
    "    X_test_scaled = scaler.transform(X_test)\n",
    "    rf_classifier = RandomForestClassifier(random_state=42, n_estimators=1000, max_depth=3, n_jobs=-1)\n",
    "    rf_classifier.fit(X_train_scaled, y_train)\n",
    "\n",
    "    y_pred = rf_classifier.predict(X_test_scaled)\n",
    "\n",
    "    accuracy = accuracy_score(y_test, y_pred)\n",
    "    print(f'Accuracy of {name}: {accuracy:.2f}')"
   ]
  },
  {
   "cell_type": "code",
   "execution_count": null,
   "metadata": {},
   "outputs": [],
   "source": []
  }
 ],
 "metadata": {
  "kernelspec": {
   "display_name": "Python 3 (ipykernel)",
   "language": "python",
   "name": "python3"
  },
  "language_info": {
   "codemirror_mode": {
    "name": "ipython",
    "version": 3
   },
   "file_extension": ".py",
   "mimetype": "text/x-python",
   "name": "python",
   "nbconvert_exporter": "python",
   "pygments_lexer": "ipython3",
   "version": "3.9.18"
  }
 },
 "nbformat": 4,
 "nbformat_minor": 2
}
